Workbook

Sheet Hoja 4
A1: N° C.I. | B1: Nombre y Apellido | C1: Cat. Código | D1: Presupuestado | E1: Exposicion al Peligro | F1: Jubilación | G1: Giraduría | H1: Descuento CF2 | I1: Judicial | J1: Total Desc. | K1: Líquido | L1: Cod. Unidad | M1: Unidad
A2: 1093298 | B2: ALCIDES LOVERA ORTIZ | C2: M02 | D2: 13915400 | E2: =IFERROR(VLOOKUP(A2, Hoja1!B:H, 7, FALSE), 0) -> 1989907 | F2: 2643930 | G2: 5079000 | H2: 1573000 | I2: 0 | J2: 6652000 | K2: =D2-(F2+G2+H2+I2) -> 4619470 | L2: 1 | M2: COMANJEFE
A3: 1131603 | B3: ALFREDO LUIS OJEDA BRITEZ | C3: M08 | D3: 11886100 | E3: =IFERROR(VLOOKUP(A3, Hoja1!B:H, 7, FALSE), 0) -> 1414446 | F3: 2258360 | G3: 3398480 | H3: 1157000 | I3: 0 | J3: 4555480 | K3: =D3-(F3+G3+H3+I3) -> 5072260 | L3: 1 | M3: COMANJEFE
A4: 1135667 | B4: CARLOS JAVIER MIRANDA ENCINA | C4: M07 | D4: 12176000 | E4: =IFERROR(VLOOKUP(A4, Hoja1!B:H, 7, FALSE), 0) -> 1461120 | F4: 2313440 | G4: 45000 | H4: 636000 | I4: 0 | J4: 681000 | K4: =D4-(F4+G4+H4+I4) -> 9181560 | L4: 1 | M4: COMANJEFE
A5: 1147259 | B5: ALFREDO GABRIEL GRANCE LEZCANO | C5: M02 | D5: 13915400 | E5: =IFERROR(VLOOKUP(A5, Hoja1!B:H, 7, FALSE), 0) -> 1989907 | F5: 2643930 | G5: 1006840 | H5: 3117690 | I5: 0 | J5: 4124520 | K5: =D5-(F5+G5+H5+I5) -> 7146940 | L5: 1 | M5: COMANJEFE
A6: 1160653 | B6: NERY TORRES LACONICH | C6: M02 | D6: 13915400 | E6: =IFERROR(VLOOKUP(A6, Hoja1!B:H, 7, FALSE), 0) -> 1989907 | F6: 2643930 | G6: 0 | H6: 1656270 | I6: 0 | J6: 1656270 | K6: =D6-(F6+G6+H6+I6) -> 9615200 | L6: 1 | M6: COMANJEFE
A7: 1182901 | B7: ROBERTO CARLOS OLMEDO LESME | C7: M02 | D7: 13915400 | E7: =IFERROR(VLOOKUP(A7, Hoja1!B:H, 7, FALSE), 0) -> 1989907 | F7: 2643930 | G7: 45000 | H7: 2254270 | I7: 0 | J7: 2299270 | K7: =D7-(F7+G7+H7+I7) -> 8972200 | L7: 1 | M7: COMANJEFE
A8: 1183745 | B8: ORLANDO FAVIO VILLALBA LOPEZ | C8: M09 | D8: 11596200 | E8: =IFERROR(VLOOKUP(A8, Hoja1!B:H, 7, FALSE), 0) -> 1229197 | F8: 2203280 | G8: 1805020 | H8: 594000 | I8: 0 | J8: 2399020 | K8: =D8-(F8+G8+H8+I8) -> 6993900 | L8: 1 | M8: COMANJEFE
A9: 1188658 | B9: CARLOS RAUL KARJALLO BENITEZ | C9: M03 | D9: 13335600 | E9: =IFERROR(VLOOKUP(A9, Hoja1!B:H, 7, FALSE), 0) -> 1933665 | F9: 2533770 | G9: 380000 | H9: 3056620 | I9: 0 | J9: 3436620 | K9: =D9-(F9+G9+H9+I9) -> 7365210 | L9: 1 | M9: COMANJEFE
A10: 1194609 | B10: TERESA CONCEPCION BRITEZ DE MENDOZA | C10: M03 | D10: 13335600 | E10: =IFERROR(VLOOKUP(A10, Hoja1!B:H, 7, FALSE), 0) -> 1933665 | F10: 2533770 | G10: 0 | H10: 426000 | I10: 0 | J10: 426000 | K10: =D10-(F10+G10+H10+I10) -> 10375830 | L10: 1 | M10: COMANJEFE
A11: 1228403 | B11: HUGO DANIEL AYALA URBIETA | C11: M03 | D11: 13335600 | E11: =IFERROR(VLOOKUP(A11, Hoja1!B:H, 7, FALSE), 0) -> 1933665 | F11: 2533770 | G11: 45000 | H11: 1126000 | I11: 0 | J11: 1171000 | K11: =D11-(F11+G11+H11+I11) -> 9630830 | L11: 1 | M11: COMANJEFE
A12: 1229509 | B12: JORGE DIONICIO CANO VILLALBA | C12: M02 | D12: 13915400 | E12: =IFERROR(VLOOKUP(A12, Hoja1!B:H, 7, FALSE), 0) -> 1989907 | F12: 2643930 | G12: 0 | H12: 1551000 | I12: 0 | J12: 1551000 | K12: =D12-(F12+G12+H12+I12) -> 9720470 | L12: 1 | M12: COMANJEFE
A13: 1231011 | B13: NELSON AUGUSTO ORTIZ ESPINOZA | C13: M03 | D13: 13335600 | E13: =IFERROR(VLOOKUP(A13, Hoja1!B:H, 7, FALSE), 0) -> 1933665 | F13: 2533770 | G13: 79000 | H13: 1465000 | I13: 0 | J13: 1544000 | K13: =D13-(F13+G13+H13+I13) -> 9257830 | L13: 1 | M13: COMANJEFE
... A10359: 8096573 | B10359: WILSON RAMON ORTIZ | C10359: M64 | D10359: 3478860 | E10359: =IFERROR(VLOOKUP(A10359, Hoja1!B:H, 7, FALSE), 0) -> 361801 | F10359: 660983 | G10359: 903360 | H10359: 686477 | I10359: 0 | J10359: 1589840 | K10359: =D10359-(F10359+G10359+H10359+I10359) -> 1228040 | L10359: 401 | M10359: BCEF

Sheet Hoja1
A1: EXPOSICION AL PELIGRO | B1: 4891602 | C1: FABIO LEONARDO | D1: ZARATE BENITEZ | E1: 35476 | F1: M | G1: SUB OF. 2DA. (7 AÑOS 1 MES) | H1: 394271 | I1: 394271 | J1: CF N° 3 | K1: DAF-ARPA
A2: EXPOSICION AL PELIGRO | B2: 6902811 | C2: FERNANDO LUIS | D2: ROA TALAVERA | E2: 36254 | F2: M | G2: SARG. 1RO. (4 AÑOS 1 MES) | H2: 369339 | I2: 369339 | J2: CF N° 2 | K2: DAF-FFTT
A3: EXPOSICION AL PELIGRO | B3: 5918294 | C3: IVAN DAVID | D3: SOSA BAREIRO | E3: 36345 | F3: M | G3: SARG. 1RO. (4 AÑOS 1 MES) | H3: 369339 | I3: 369339 | J3: CF N° 2 | K3: DAF-FFTT
A4: EXPOSICION AL PELIGRO | B4: 2047156 | C4: JOSE DOMINGO | D4: AYALA RUIZ DIAZ | E4: 29775 | F4: M | G4: SUB OF. (20 AÑOS 1 MES) | H4: 513131 | I4: 513131 | J4: CF N° 4 | K4: AFFAP
A5: EXPOSICION AL PELIGRO | B5: 4458945 | C5: FRANCISCO RODOLFO | D5: VALLEJOS ESCOBAR | E5: 32235 | F5: M | G5: SUB OF. (18 AÑOS 1 MES) | H5: 503275 | I5: 503275 | J5: CF N° 4 | K5: AFFAP
A6: EXPOSICION AL PELIGRO | B6: 6178373 | C6: FREDY RODRIGO | D6: ESCOBAR FERREIRA | E6: 37727 | F6: M | G6: VICE STO. 1RO. (1 AÑO 1 MES) | H6: 353974 | I6: 353974 | J6: CF N° 2 | K6: DAF-FFTT
A7: EXPOSICION AL PELIGRO | B7: 3458198 | C7: ARNALDO RAMON | D7: CARDOZO GARCIA | E7: 29413 | F7: M | G7: SUB OF. MAY. (21 AÑOS 1 MES) | H7: 521249 | I7: 521249 | J7: CF N° 2 | K7: DAF-FFTT
A8: EXPOSICION AL PELIGRO | B8: 5125458 | C8: LUIS ANTONIO | D8: DIAZ ARGÜELLO | E8: 33768 | F8: M | G8: SARG. AYUD. (14 AÑOS 1 MES) | H8: 0 | I8: 0 | J8: CF N° 2 | K8: DAF-FFTT
A9: EXPOSICION AL PELIGRO | B9: 4846218 | C9: JAZMIN ARACI | D9: PORTILLO GONZALEZ | E9: 34553 | F9: F | G9: SUB TTE. (1 AÑO 1 MES) | H9: 384994 | I9: 384994 | J9: CF N° 2 | K9: DAF-FFTT
A10: EXPOSICION AL PELIGRO | B10: 4681114 | C10: TEODOCIO | D10: VILLAR MOREL | E10: 31776 | F10: M | G10: SUB OF. (17 AÑOS 1 MES) | H10: 493128 | I10: 493128 | J10: CF N° 2 | K10: DAF-FFTT
A11: EXPOSICION AL PELIGRO | B11: 6358549 | C11: NELSON MARCIAL | D11: SOSA CARDOZO | E11: 36103 | F11: M | G11: SARG. 1RO. (6 AÑOS 1 MES) | H11: 380355 | I11: 380355 | J11: CF N° 4 | K11: AFFAP
A12: EXPOSICION AL PELIGRO | B12: 6039267 | C12: FABIO IVAN | D12: AYALA CAÑETE | E12: 36399 | F12: M | G12: SUB OF. 2DA. (4 AÑOS 1 MES) | H12: 369339 | I12: 369339 | J12: CF N° 3 | K12: DAF-ARPA
... A1452: EXPOSICION AL PELIGRO | B1452: 5067682 | C1452: CELSO ADRIAN | D1452: YAHARI BENITEZ | E1452: 34965 | F1452: M | G1452: SARG. 1RO. (9 AÑOS 1 MES) | H1452: 407606 | I1452: 407606 | J1452: CF N° 2 | K1452: DAF-FFTT
A1453: EXPOSICION AL PELIGRO | B1453: 1652239 | C1453: JUAN BAUTISTA | D1453: GALEANO GAMARRA | E1453: 1811-01-01 | F1453: M | G1453: SUB OF. MAY. (24 AÑOS 1 MES) | H1453: 551979 | I1453: 551979 | J1453: CF N° 2 | K1453: DAF-FFTT
A1454: EXPOSICION AL PELIGRO | B1454: 4501662 | C1454: JUSTO VIDAL | D1454: BORDON PAREDES | E1454: 31805 | F1454: M | G1454: SARG. AYUD. (14 AÑOS 1 MES) | H1454: 445294 | I1454: 445294 | J1454: CF N° 2 | K1454: DAF-FFTT
A1455: EXPOSICION AL PELIGRO | B1455: 5513204 | C1455: JORGE DANIEL | D1455: MARTINEZ DIAZ | E1455: 32669 | F1455: M | G1455: SARG. AYUD. (11 AÑOS 1 MES) | H1455: 413984 | I1455: 413984 | J1455: CF N° 2 | K1455: DAF-FFTT
A1456: EXPOSICION AL PELIGRO | B1456: 5522205 | C1456: WALTER JESUS | D1456: VELAZQUEZ ROJAS | E1456: 37589 | F1456: M | G1456: SUB OF. 3RA. (1 AÑO 1 MES) | H1456: 353974 | I1456: 353974 | J1456: CF N° 3 | K1456: DAF-ARPA
A1457: EXPOSICION AL PELIGRO | B1457: 5380174 | C1457: RODRIGO | D1457: AGUILAR BENITEZ | E1457: 36232 | F1457: M | G1457: SUB OF. 2DA. (7 AÑOS 1 MES) | H1457: 394271 | I1457: 394271 | J1457: CF N° 3 | K1457: DAF-ARPA
A1458: EXPOSICION AL PELIGRO | B1458: 7211186 | C1458: JOEL DAVID | D1458: ARAUJO CASTILLO | E1458: 37162 | F1458: M | G1458: SARG. 1RO. (4 AÑOS 1 MES) | H1458: 369339 | I1458: 369339 | J1458: CF N° 2 | K1458: DAF-FFTT
A1459: EXPOSICION AL PELIGRO | B1459: 5371510 | C1459: JOSE | D1459: DIAZ CANO | E1459: 33682 | F1459: M | G1459: SARG. AYUD. (13 AÑOS 1 MES) | H1459: 433408 | I1459: 433408 | J1459: CF N° 2 | K1459: DAF-FFTT
A1460: EXPOSICION AL PELIGRO | B1460: 5305493 | C1460: OSMAR CARLOS | D1460: BENEGAS VILLAMAYOR | E1460: 34443 | F1460: M | G1460: SARG. AYUD. (11 AÑOS 1 MES) | H1460: 413984 | I1460: 413984 | J1460: CF N° 2 | K1460: DAF-FFTT
A1461: EXPOSICION AL PELIGRO | B1461: 4573687 | C1461: JUAN DE JESUS | D1461: LESME VILLAGRA | E1461: 33610 | F1461: M | G1461: SARG. AYUD. (13 AÑOS 1 MES) | H1461: 433408 | I1461: 433408 | J1461: CF N° 2 | K1461: DAF-FFTT
A1462: EXPOSICION AL PELIGRO | B1462: 6279056 | C1462: RICHARD BENITO | D1462: LARREA | E1462: 35869 | F1462: M | G1462: SARG. 1RO. (6 AÑOS 1 MES) | H1462: 1103958 | I1462: 1103958 | J1462: CF N° 2 | K1462: DAF-FFTT
A1463: EXPOSICION AL PELIGRO | B1463: 2483607 | C1463: ALFREDO MANUEL | D1463: SENES VALIENTE | E1463: 28139 | F1463: M | G1463: CORONEL (26 AÑOS 1 MES) | H1463: 1414446 | I1463: 1414446 | J1463: CF N° 2 | K1463: DAF-FFTT
A1464: EXPOSICION AL PELIGRO | B1464: 7185084 | C1464: MILCIADES ARIEL | D1464: PAIVA | E1464: 36918 | F1464: M | G1464: VICE STO. 1RO. (2 AÑOS 1 MES) | H1464: 361801 | I1464: 361801 | J1464: CF N° 2 | K1464: DAF-FFTT
A1465: EXPOSICION AL PELIGRO | B1465: 6824219 | C1465: HERIC IGNACIO | D1465: FERNANDEZ CANTERO | E1465: 38011 | F1465: M | G1465: SUB OF. 3RA. (1 AÑO 1 MES) | H1465: 353974 | I1465: 353974 | J1465: CF N° 3 | K1465: DAF-ARPA
... A16602: EXPOSICION AL PELIGRO | B16602: 5287955 | C16602: KAMILA YANET | D16602: BOBADILLA OCAMPOS | E16602: 38145 | F16602: F | G16602: VICE STO. 1RO. (1 AÑO 1 MES) | H16602: 353974 | I16602: 353974 | J16602: CF N° 2 | K16602: DAF-FFTT
A16603: EXPOSICION AL PELIGRO | B16603: 3179773 | C16603: LUIS ANIBAL | D16603: SERVIAN AGUILERA | E16603: 1811-01-01 | F16603: M | G16603: SUB OF. (16 AÑOS 1 MES) | H16603: 474864 | I16603: 474864 | J16603: CF N° 3 | K16603: DAF-ARPA
A16604: EXPOSICION AL PELIGRO | B16604: 5170133 | C16604: ESTER CAROLINA | D16604: CAÑETE HERMOSA | E16604: 36558 | F16604: F | G16604: SARG. 1RO. (6 AÑOS 1 MES) | H16604: 380355 | I16604: 380355 | J16604: CF N° 2 | K16604: DAF-FFTT
A16605: EXPOSICION AL PELIGRO | B16605: 6775915 | C16605: RICHARD GABRIEL | D16605: GONZALEZ BENITEZ | E16605: 34760 | F16605: M | G16605: SARG. 1RO. (9 AÑOS 1 MES) | H16605: 407606 | I16605: 407606 | J16605: CF N° 2 | K16605: DAF-FFTT
A16606: EXPOSICION AL PELIGRO | B16606: 3353460 | C16606: RAUL ROBERTO | D16606: BENITEZ AGUILERA | E16606: 29157 | F16606: M | G16606: SUB OF. MAY. (22 AÑOS 1 MES) | H16606: 528786 | I16606: 528786 | J16606: CF N° 4 | K16606: AFFAP
A16607: EXPOSICION AL PELIGRO | B16607: 4886442 | C16607: NOLBERTO | D16607: BRACHO MONGES | E16607: 32689 | F16607: M | G16607: SARG. AYUD. (13 AÑOS 1 MES) | H16607: 433408 | I16607: 433408 | J16607: CF N° 2 | K16607: DAF-FFTT
A16608: EXPOSICION AL PELIGRO | B16608: 4892423 | C16608: GLORIA BEATRIZ | D16608: GOMEZ ARCE | E16608: 35326 | F16608: F | G16608: SUB OF. 2DA. (6 AÑOS 1 MES) | H16608: 380355 | I16608: 380355 | J16608: CF N° 3 | K16608: DAF-ARPA
A16609: EXPOSICION AL PELIGRO | B16609: 4731984 | C16609: INOCENTE | D16609: ESCOBAR RODRIGUEZ | E16609: 32505 | F16609: M | G16609: SUB OF. (17 AÑOS 1 MES) | H16609: 493128 | I16609: 493128 | J16609: CF N° 2 | K16609: DAF-FFTT
A16610: EXPOSICION AL PELIGRO | B16610: 6051713 | C16610: FRANCO ELIAS | D16610: VAZQUEZ BENITEZ | E16610: 37668 | F16610: M | G16610: VICE STO. 1RO. (1 AÑO 1 MES) | H16610: 353974 | I16610: 353974 | J16610: CF N° 2 | K16610: DAF-FFTT
A16611: EXPOSICION AL PELIGRO | B16611: 6790501 | C16611: PEDRO ALCIDES | D16611: GONZALEZ PEREIRA | E16611: 35732 | F16611: M | G16611: SUB OF. 2DA. (4 AÑOS 1 MES) | H16611: 369339 | I16611: 369339 | J16611: CF N° 3 | K16611: DAF-ARPA
A16612: EXPOSICION AL PELIGRO | B16612: 7599256 | C16612: FRANCO ALEXIS | D16612: RAMIREZ GRANCE | E16612: 38052 | F16612: M | G16612: VICE STO. 1RO. (1 AÑO 1 MES) | H16612: 353974 | I16612: 353974 | J16612: CF N° 2 | K16612: DAF-FFTT
A16613: EXPOSICION AL PELIGRO | B16613: 4184677 | C16613: FERNANDO SAMUEL | D16613: BERNAL | E16613: 31198 | F16613: M | G16613: SUB OF. MAY. (22 AÑOS 1 MES) | H16613: 528786 | I16613: 528786 | J16613: CF N° 3 | K16613: DAF-ARPA
A16614: EXPOSICION AL PELIGRO | B16614: 5117938 | C16614: DOMINGO GUZMAN | D16614: BENITEZ MARECO | E16614: 33709 | F16614: M | G16614: SARG. AYUD. (11 AÑOS 1 MES) | H16614: 413984 | I16614: 413984 | J16614: CF N° 2 | K16614: DAF-FFTT
A16615: EXPOSICION AL PELIGRO | B16615: 5339344 | C16615: CESAR | D16615: ROJAS OZUNA | E16615: 32443 | F16615: M | G16615: SUB OF. 1RA. (13 AÑOS 1 MES) | H16615: 433408 | I16615: 433408 | J16615: CF N° 3 | K16615: DAF-ARPA
...
