Workbook

Sheet Hoja1
A1: Nro. Socio | B1: Nombre y Apellido | C1: Nro. Cédula
A2: 13 | B2: MARTINEZ ESTIGARRIBA, AMADO JESUS | C2: 270420
A3: 17 | B3: BRITEZ UGARTE, ANTONIO BERNABE | C3: 286092
A4: 18 | B4: BAREIRO SANCHEZ, VICTOR ISIDRO | C4: 343995
A5: 22 | B5: GONZALEZ MARTINEZ, VIRGILIO | C5: 442422
A6: 26 | B6: QUINTANA RAMIREZ, RUFINO | C6: 501649
A7: 28 | B7: PENAYO ROJAS, ANGEL FLORENTIN | C7: 315983
A8: 29 | B8: ESQUIVEL CABALLERO, RAMON RICARDO | C8: 367112
A9: 31 | B9: KUNZLE FIGUEREDO, FELIX OVIDIO | C9: 353036
A10: 38 | B10: MENDIETA ALVARENGA, EMILIO | C10: 405706
A11: 39 | B11: MEDINA CABALLERO, FRANCISCO HIPOLITO | C11: 431881
A12: 40 | B12: OZORIO CORONEL, VICTORINO JULIO | C12: 377215
A13: 41 | B13: SCHEMBORI MEDINA, LUIS | C13: 453114
... A5475: 13790 | B5475: BENITEZ CUELLAR, FRANCISCO JAVIER | C5475: 8077340

Sheet Unidad 1
A1: N° | B1: N° Socio | C1: N° de CI | D1: Apellido y Nombre | E1: Total Descuentos | F1: Cobrado | G1: Rechazado
A2: 1 | B2: =IFERROR(INDEX(Hoja1!A:A,MATCH(C2,Hoja1!C:C,0)),"") -> 9946 | C2: 5955048 | D2: =IFERROR(INDEX(Hoja1!B:B,MATCH(C2,Hoja1!C:C,0)),"") -> AQUINO ARCE, DERLIS DAVID | E2: 1147945 | F2: 0 | G2: =E2-F2 -> 1147945
A3: =A2+1 -> 2 | B3: =IFERROR(INDEX(Hoja1!A:A,MATCH(C3,Hoja1!C:C,0)),"") -> 11530 | C3: 6646827 | D3: =IFERROR(INDEX(Hoja1!B:B,MATCH(C3,Hoja1!C:C,0)),"") -> SOTTO NUÑEZ, NERY DE JESUS | E3: 54000 | F3: 54000 | G3: =E3-F3 -> 0
A4: =A3+1 -> 3 | B4: =IFERROR(INDEX(Hoja1!A:A,MATCH(C4,Hoja1!C:C,0)),"") -> 11797 | C4: 7594743 | D4: =IFERROR(INDEX(Hoja1!B:B,MATCH(C4,Hoja1!C:C,0)),"") -> DIAZ GIMENEZ, ROLANDO | E4: 660103 | F4: 0 | G4: =E4-F4 -> 660103
A5: =A4+1 -> 4 | B5: =IFERROR(INDEX(Hoja1!A:A,MATCH(C5,Hoja1!C:C,0)),"") -> 11961 | C5: 2911744 | D5: =IFERROR(INDEX(Hoja1!B:B,MATCH(C5,Hoja1!C:C,0)),"") -> MONTIEL, RICARDO MANUEL | E5: 1276307 | F5: 1276307 | G5: =E5-F5 -> 0
A6: =A5+1 -> 5 | B6: =IFERROR(INDEX(Hoja1!A:A,MATCH(C6,Hoja1!C:C,0)),"") -> 12374 | C6: 6850435 | D6: =IFERROR(INDEX(Hoja1!B:B,MATCH(C6,Hoja1!C:C,0)),"") -> AGUERO DEL PADRE, LORENZO | E6: 546701 | F6: 0 | G6: =E6-F6 -> 546701
A7: Total General | E7: =SUM(E2:E6) -> 3685056 | F7: =SUM(F2:F6) -> 1330307 | G7: =SUM(G2:G6) -> 2354749

Sheet Unidad 2
A1: N° | B1: N° Socio | C1: N° de CI | D1: Apellido y Nombre | E1: Total Descuentos | F1: Cobrado | G1: Rechazado
A2: 1 | B2: =IFERROR(INDEX(Hoja1!A:A,MATCH(C2,Hoja1!C:C,0)),"") -> 2866 | C2: 3985180 | D2: =IFERROR(INDEX(Hoja1!B:B,MATCH(C2,Hoja1!C:C,0)),"") -> GUILLEN, JORGE FABIAN | E2: 313151 | F2: 313151 | G2: =E2-F2 -> 0
A3: =A2+1 -> 2 | B3: =IFERROR(INDEX(Hoja1!A:A,MATCH(C3,Hoja1!C:C,0)),"") -> 3820 | C3: 4630454 | D3: =IFERROR(INDEX(Hoja1!B:B,MATCH(C3,Hoja1!C:C,0)),"") -> MEDINA CORONEL, FREDY SEBASTIAN | E3: 1688032 | F3: 1688032 | G3: =E3-F3 -> 0
A4: =A3+1 -> 3 | B4: =IFERROR(INDEX(Hoja1!A:A,MATCH(C4,Hoja1!C:C,0)),"") -> 6083 | C4: 5081059 | D4: =IFERROR(INDEX(Hoja1!B:B,MATCH(C4,Hoja1!C:C,0)),"") -> BAEZ BENITEZ, ARNALDO | E4: 567216 | F4: 567216 | G4: =E4-F4 -> 0
A5: =A4+1 -> 4 | B5: =IFERROR(INDEX(Hoja1!A:A,MATCH(C5,Hoja1!C:C,0)),"") -> 6590 | C5: 5240321 | D5: =IFERROR(INDEX(Hoja1!B:B,MATCH(C5,Hoja1!C:C,0)),"") -> ROJAS BENITEZ, LUIS ARIEL | E5: 307608 | F5: 307608 | G5: =E5-F5 -> 0
A6: =A5+1 -> 5 | B6: =IFERROR(INDEX(Hoja1!A:A,MATCH(C6,Hoja1!C:C,0)),"") -> 6595 | C6: 5472169 | D6: =IFERROR(INDEX(Hoja1!B:B,MATCH(C6,Hoja1!C:C,0)),"") -> CABALLERO PEÑA, ROLANDO DAVID | E6: 676659 | F6: 576659 | G6: =E6-F6 -> 100000
A7: =A6+1 -> 6 | B7: =IFERROR(INDEX(Hoja1!A:A,MATCH(C7,Hoja1!C:C,0)),"") -> 6599 | C7: 5339216 | D7: =IFERROR(INDEX(Hoja1!B:B,MATCH(C7,Hoja1!C:C,0)),"") -> ESTIGARRIBIA SOSTOA, PEDRO ANTONIO | E7: 916567 | F7: 850567 | G7: =E7-F7 -> 66000
A8: =A7+1 -> 7 | B8: =IFERROR(INDEX(Hoja1!A:A,MATCH(C8,Hoja1!C:C,0)),"") -> 6600 | C8: 3036420 | D8: =IFERROR(INDEX(Hoja1!B:B,MATCH(C8,Hoja1!C:C,0)),"") -> GAMARRA GONZALEZ, HUGO HERNAN | E8: 503206 | F8: 403206 | G8: =E8-F8 -> 100000
A9: =A8+1 -> 8 | B9: =IFERROR(INDEX(Hoja1!A:A,MATCH(C9,Hoja1!C:C,0)),"") -> 7405 | C9: 5238610 | D9: =IFERROR(INDEX(Hoja1!B:B,MATCH(C9,Hoja1!C:C,0)),"") -> SOLIS VILLAMAYOR, GUSTAVO | E9: 618126 | F9: 380000 | G9: =E9-F9 -> 238126
A10: =A9+1 -> 9 | B10: =IFERROR(INDEX(Hoja1!A:A,MATCH(C10,Hoja1!C:C,0)),"") -> 8125 | C10: 6918493 | D10: =IFERROR(INDEX(Hoja1!B:B,MATCH(C10,Hoja1!C:C,0)),"") -> MARTINEZ VALLEJOS, LORENZO JAVIER | E10: 54000 | F10: 54000 | G10: =E10-F10 -> 0
A11: =A10+1 -> 10 | B11: =IFERROR(INDEX(Hoja1!A:A,MATCH(C11,Hoja1!C:C,0)),"") -> 8265 | C11: 6103899 | D11: =IFERROR(INDEX(Hoja1!B:B,MATCH(C11,Hoja1!C:C,0)),"") -> BENITEZ LOPEZ, ARNALDO | E11: 765164 | F11: 765164 | G11: =E11-F11 -> 0
A12: =A11+1 -> 11 | B12: =IFERROR(INDEX(Hoja1!A:A,MATCH(C12,Hoja1!C:C,0)),"") -> 8308 | C12: 4883076 | D12: =IFERROR(INDEX(Hoja1!B:B,MATCH(C12,Hoja1!C:C,0)),"") -> GONZALEZ VILLAR, CELSO RAMON | E12: 868016 | F12: 868016 | G12: =E12-F12 -> 0
A13: =A12+1 -> 12 | B13: =IFERROR(INDEX(Hoja1!A:A,MATCH(C13,Hoja1!C:C,0)),"") -> 8386 | C13: 3505044 | D13: =IFERROR(INDEX(Hoja1!B:B,MATCH(C13,Hoja1!C:C,0)),"") -> TABARELLI LEZCANO, ISIDRO LUIS | E13: 451008 | F13: 451008 | G13: =E13-F13 -> 0
A14: =A13+1 -> 13 | B14: =IFERROR(INDEX(Hoja1!A:A,MATCH(C14,Hoja1!C:C,0)),"") -> 8387 | C14: 1683029 | D14: =IFERROR(INDEX(Hoja1!B:B,MATCH(C14,Hoja1!C:C,0)),"") -> TABARELLI LEZCANO, MIRNA LUZ | E14: 451008 | F14: 451008 | G14: =E14-F14 -> 0
... A23: =A22+1 -> 22 | B23: =IFERROR(INDEX(Hoja1!A:A,MATCH(C23,Hoja1!C:C,0)),"") -> 11903 | C23: 6561150 | D23: =IFERROR(INDEX(Hoja1!B:B,MATCH(C23,Hoja1!C:C,0)),"") -> OBREGON CARDOZO, ARIEL | E23: 522750 | F23: 522750 | G23: =E23-F23 -> 0
A24: Total General | E24: =SUM(E2:E23) -> 13419035 | F24: =SUM(F2:F23) -> 12809341 | G24: =SUM(G2:G23) -> 609694

Sheet Unidad 3
A1: N° | B1: N° Socio | C1: N° de CI | D1: Apellido y Nombre | E1: Total Descuentos | F1: Cobrado | G1: Rechazado
A2: 1 | B2: =IFERROR(INDEX(Hoja1!A:A,MATCH(C2,Hoja1!C:C,0)),"") -> 3945 | C2: 3634368 | D2: =IFERROR(INDEX(Hoja1!B:B,MATCH(C2,Hoja1!C:C,0)),"") -> CRUZ MARTINEZ, REINALDO ARNALDO | E2: 534410 | F2: 234000 | G2: =E2-F2 -> 300410
A3: =A2+1 -> 2 | B3: =IFERROR(INDEX(Hoja1!A:A,MATCH(C3,Hoja1!C:C,0)),"") -> 5251 | C3: 5491200 | D3: =IFERROR(INDEX(Hoja1!B:B,MATCH(C3,Hoja1!C:C,0)),"") -> QUIÑONEZ ESCOBAR, EVER HUGO | E3: 951417 | F3: 951417 | G3: =E3-F3 -> 0
A4: =A3+1 -> 3 | B4: =IFERROR(INDEX(Hoja1!A:A,MATCH(C4,Hoja1!C:C,0)),"") -> 5981 | C4: 4966602 | D4: =IFERROR(INDEX(Hoja1!B:B,MATCH(C4,Hoja1!C:C,0)),"") -> ROJAS VILLAVERDE, VENANCIO | E4: 34000 | F4: 34000 | G4: =E4-F4 -> 0
A5: =A4+1 -> 4 | B5: =IFERROR(INDEX(Hoja1!A:A,MATCH(C5,Hoja1!C:C,0)),"") -> 9036 | C5: 5578105 | D5: =IFERROR(INDEX(Hoja1!B:B,MATCH(C5,Hoja1!C:C,0)),"") -> DOS SANTOS LOPEZ, PABLO CESAR | E5: 978027 | F5: 0 | G5: =E5-F5 -> 978027
A6: =A5+1 -> 5 | B6: =IFERROR(INDEX(Hoja1!A:A,MATCH(C6,Hoja1!C:C,0)),"") -> 9357 | C6: 6032438 | D6: =IFERROR(INDEX(Hoja1!B:B,MATCH(C6,Hoja1!C:C,0)),"") -> MUÑOZ FERNANDEZ, JONAS AMERICO | E6: 1589127 | F6: 0 | G6: =E6-F6 -> 1589127
A7: =A6+1 -> 6 | B7: =IFERROR(INDEX(Hoja1!A:A,MATCH(C7,Hoja1!C:C,0)),"") -> 9564 | C7: 3677760 | D7: =IFERROR(INDEX(Hoja1!B:B,MATCH(C7,Hoja1!C:C,0)),"") -> ALVARENGA VAZQUEZ, ALVARO RODRIGO | E7: 226723 | F7: 226723 | G7: =E7-F7 -> 0
A8: =A7+1 -> 7 | B8: =IFERROR(INDEX(Hoja1!A:A,MATCH(C8,Hoja1!C:C,0)),"") -> 9992 | C8: 5106299 | D8: =IFERROR(INDEX(Hoja1!B:B,MATCH(C8,Hoja1!C:C,0)),"") -> ESTIGARRIBIA GONZALEZ, WILDER PAUL | E8: 601216 | F8: 601216 | G8: =E8-F8 -> 0
A9: =A8+1 -> 8 | B9: =IFERROR(INDEX(Hoja1!A:A,MATCH(C9,Hoja1!C:C,0)),"") -> 10119 | C9: 4020335 | D9: =IFERROR(INDEX(Hoja1!B:B,MATCH(C9,Hoja1!C:C,0)),"") -> FERREIRA ESCARIO, JHONY AARON | E9: 437246 | F9: 0 | G9: =E9-F9 -> 437246
A10: Total General | E10: =SUM(E2:E9) -> 5352166 | F10: =SUM(F2:F9) -> 2047356 | G10: =SUM(G2:G9) -> 3304810

Sheet Unidad 4
A1: N° | B1: N° Socio | C1: N° de CI | D1: Apellido y Nombre | E1: Total Descuentos | F1: Cobrado | G1: Rechazado
A2: 1 | B2: =IFERROR(INDEX(Hoja1!A:A,MATCH(C2,Hoja1!C:C,0)),"") -> 1914 | C2: 4475450 | D2: =IFERROR(INDEX(Hoja1!B:B,MATCH(C2,Hoja1!C:C,0)),"") -> ROJAS BOGADO, ANGEL MARIA | E2: 773459 | F2: 0 | G2: =E2-F2 -> 773459
A3: =A2+1 -> 2 | B3: =IFERROR(INDEX(Hoja1!A:A,MATCH(C3,Hoja1!C:C,0)),"") -> 5145 | C3: 4505754 | D3: =IFERROR(INDEX(Hoja1!B:B,MATCH(C3,Hoja1!C:C,0)),"") -> ECHEVERRIA, LUIS MARIA | E3: 34000 | F3: 34000 | G3: =E3-F3 -> 0
A4: =A3+1 -> 3 | B4: =IFERROR(INDEX(Hoja1!A:A,MATCH(C4,Hoja1!C:C,0)),"") -> 5692 | C4: 3446207 | D4: =IFERROR(INDEX(Hoja1!B:B,MATCH(C4,Hoja1!C:C,0)),"") -> CUBILLA FRANCO, JOSE RAMON | E4: 868016 | F4: 868016 | G4: =E4-F4 -> 0
A5: =A4+1 -> 4 | B5: =IFERROR(INDEX(Hoja1!A:A,MATCH(C5,Hoja1!C:C,0)),"") -> 5904 | C5: 4185937 | D5: =IFERROR(INDEX(Hoja1!B:B,MATCH(C5,Hoja1!C:C,0)),"") -> MORENO SANCHEZ, PAULINO ANDRES | E5: 334000 | F5: 334000 | G5: =E5-F5 -> 0
A6: =A5+1 -> 5 | B6: =IFERROR(INDEX(Hoja1!A:A,MATCH(C6,Hoja1!C:C,0)),"") -> 6075 | C6: 5001897 | D6: =IFERROR(INDEX(Hoja1!B:B,MATCH(C6,Hoja1!C:C,0)),"") -> GONZALEZ ACOSTA, CARLOS GABRIEL | E6: 1422954 | F6: 1422954 | G6: =E6-F6 -> 0
A7: =A6+1 -> 6 | B7: =IFERROR(INDEX(Hoja1!A:A,MATCH(C7,Hoja1!C:C,0)),"") -> 6439 | C7: 2604303 | D7: =IFERROR(INDEX(Hoja1!B:B,MATCH(C7,Hoja1!C:C,0)),"") -> ORTIZ, DIEGO ANTONIO | E7: 2128949 | F7: 2128949 | G7: =E7-F7 -> 0
A8: =A7+1 -> 7 | B8: =IFERROR(INDEX(Hoja1!A:A,MATCH(C8,Hoja1!C:C,0)),"") -> 6492 | C8: 2368443 | D8: =IFERROR(INDEX(Hoja1!B:B,MATCH(C8,Hoja1!C:C,0)),"") -> TORRES SARUBBI, OSVALDO DARIO | E8: 406700 | F8: 0 | G8: =E8-F8 -> 406700
A9: =A8+1 -> 8 | B9: =IFERROR(INDEX(Hoja1!A:A,MATCH(C9,Hoja1!C:C,0)),"") -> 6495 | C9: 4295157 | D9: =IFERROR(INDEX(Hoja1!B:B,MATCH(C9,Hoja1!C:C,0)),"") -> BRITOS GONZALEZ, RODNEY DANIEL | E9: 566862 | F9: 566862 | G9: =E9-F9 -> 0
A10: =A9+1 -> 9 | B10: =IFERROR(INDEX(Hoja1!A:A,MATCH(C10,Hoja1!C:C,0)),"") -> 7406 | C10: 4499811 | D10: =IFERROR(INDEX(Hoja1!B:B,MATCH(C10,Hoja1!C:C,0)),"") -> ROA AYALA, MARCELO DAVID | E10: 1283113 | F10: 0 | G10: =E10-F10 -> 1283113
A11: =A10+1 -> 10 | B11: =IFERROR(INDEX(Hoja1!A:A,MATCH(C11,Hoja1!C:C,0)),"") -> 7948 | C11: 4974064 | D11: =IFERROR(INDEX(Hoja1!B:B,MATCH(C11,Hoja1!C:C,0)),"") -> CHAPARRO GOMEZ, ARNALDO ARIEL | E11: 690659 | F11: 690659 | G11: =E11-F11 -> 0
A12: =A11+1 -> 11 | B12: =IFERROR(INDEX(Hoja1!A:A,MATCH(C12,Hoja1!C:C,0)),"") -> 10506 | C12: 4630610 | D12: =IFERROR(INDEX(Hoja1!B:B,MATCH(C12,Hoja1!C:C,0)),"") -> SOSA FLOR, CESAR ANIBAL | E12: 3445159 | F12: 2000000 | G12: =E12-F12 -> 1445159
A13: Total General | E13: =SUM(E2:E12) -> 11953871 | F13: =SUM(F2:F12) -> 8045440 | G13: =SUM(G2:G12) -> 3908431

Sheet Unidad 5
A1: N° | B1: N° Socio | C1: N° de CI | D1: Apellido y Nombre | E1: Total Descuentos | F1: Cobrado | G1: Rechazado
A2: 1 | B2: =IFERROR(INDEX(Hoja1!A:A,MATCH(C2,Hoja1!C:C,0)),"") -> 5258 | C2: 1380191 | D2: =IFERROR(INDEX(Hoja1!B:B,MATCH(C2,Hoja1!C:C,0)),"") -> SERVIN BRITEZ, FERNANDO ANDRES | E2: 1455210 | F2: 1455210 | G2: =E2-F2 -> 0
A3: =A2+1 -> 2 | B3: =IFERROR(INDEX(Hoja1!A:A,MATCH(C3,Hoja1!C:C,0)),"") -> 11147 | C3: 6648448 | D3: =IFERROR(INDEX(Hoja1!B:B,MATCH(C3,Hoja1!C:C,0)),"") -> BENITEZ ALLENDE, FAUSTINO | E3: 527758 | F3: 527758 | G3: =E3-F3 -> 0
A4: =A3+1 -> 3 | B4: =IFERROR(INDEX(Hoja1!A:A,MATCH(C4,Hoja1!C:C,0)),"") -> 11581 | C4: 5896067 | D4: =IFERROR(INDEX(Hoja1!B:B,MATCH(C4,Hoja1!C:C,0)),"") -> NUÑEZ GONZALEZ, MARCO JAVIER | E4: 500951 | F4: 0 | G4: =E4-F4 -> 500951
A5: =A4+1 -> 4 | B5: =IFERROR(INDEX(Hoja1!A:A,MATCH(C5,Hoja1!C:C,0)),"") -> 12377 | C5: 2564284 | D5: =IFERROR(INDEX(Hoja1!B:B,MATCH(C5,Hoja1!C:C,0)),"") -> ALMADA ALONZO, CLAUDIO | E5: 1050508 | F5: 0 | G5: =E5-F5 -> 1050508
A6: Total General | E6: =SUM(E2:E5) -> 3534427 | F6: =SUM(F2:F5) -> 1982968 | G6: =SUM(G2:G5) -> 1551459

Sheet Unidad 6
A1: N° | B1: N° Socio | C1: N° de CI | D1: Apellido y Nombre | E1: Total Descuentos | F1: Cobrado | G1: Rechazado
A2: 1 | B2: =IFERROR(INDEX(Hoja1!A:A,MATCH(C2,Hoja1!C:C,0)),"") -> 2782 | C2: 534322 | D2: =IFERROR(INDEX(Hoja1!B:B,MATCH(C2,Hoja1!C:C,0)),"") -> BONUSI MACHUCA, MARIA ELENA | E2: 34000 | F2: 34000 | G2: =E2-F2 -> 0
A3: =A2+1 -> 2 | B3: =IFERROR(INDEX(Hoja1!A:A,MATCH(C3,Hoja1!C:C,0)),"") -> 3702 | C3: 3650427 | D3: =IFERROR(INDEX(Hoja1!B:B,MATCH(C3,Hoja1!C:C,0)),"") -> PALACIOS, OSCAR BASILIO | E3: 379183 | F3: 379183 | G3: =E3-F3 -> 0
A4: =A3+1 -> 3 | B4: =IFERROR(INDEX(Hoja1!A:A,MATCH(C4,Hoja1!C:C,0)),"") -> 9229 | C4: 3897679 | D4: =IFERROR(INDEX(Hoja1!B:B,MATCH(C4,Hoja1!C:C,0)),"") -> NUÑEZ FERREIRA, CELSO RAUL | E4: 359795 | F4: 0 | G4: =E4-F4 -> 359795
A5: Total General | E5: =SUM(E2:E4) -> 772978 | F5: =SUM(F2:F4) -> 413183 | G5: =SUM(G2:G4) -> 359795

Sheet Unidad 7
A1: N° | B1: N° Socio | C1: N° de CI | D1: Apellido y Nombre | E1: Total Descuentos | F1: Cobrado | G1: Rechazado
A2: 1 | B2: =IFERROR(INDEX(Hoja1!A:A,MATCH(C2,Hoja1!C:C,0)),"") -> 2166 | C2: 2496366 | D2: =IFERROR(INDEX(Hoja1!B:B,MATCH(C2,Hoja1!C:C,0)),"") -> PEÑA ROLON, HUGO DANIEL | E2: 710659 | F2: 0 | G2: =E2-F2 -> 710659
A3: =A2+1 -> 2 | B3: =IFERROR(INDEX(Hoja1!A:A,MATCH(C3,Hoja1!C:C,0)),"") -> 2174 | C3: 3475622 | D3: =IFERROR(INDEX(Hoja1!B:B,MATCH(C3,Hoja1!C:C,0)),"") -> CORONEL PORTILLO, ISABELINO | E3: 1360851 | F3: 1085000 | G3: =E3-F3 -> 275851
A4: =A3+1 -> 3 | B4: =IFERROR(INDEX(Hoja1!A:A,MATCH(C4,Hoja1!C:C,0)),"") -> 2179 | C4: 2538098 | D4: =IFERROR(INDEX(Hoja1!B:B,MATCH(C4,Hoja1!C:C,0)),"") -> BOGADO MORALES, DARIO FROILAN | E4: 2151572 | F4: 1000000 | G4: =E4-F4 -> 1151572
A5: =A4+1 -> 4 | B5: =IFERROR(INDEX(Hoja1!A:A,MATCH(C5,Hoja1!C:C,0)),"") -> 2207 | C5: 4567384 | D5: =IFERROR(INDEX(Hoja1!B:B,MATCH(C5,Hoja1!C:C,0)),"") -> ENCINA VELAZQUEZ, JORGE ANDRES | E5: 2488281 | F5: 2000000 | G5: =E5-F5 -> 488281
A6: =A5+1 -> 5 | B6: =IFERROR(INDEX(Hoja1!A:A,MATCH(C6,Hoja1!C:C,0)),"") -> 2568 | C6: 2597078 | D6: =IFERROR(INDEX(Hoja1!B:B,MATCH(C6,Hoja1!C:C,0)),"") -> CANDIA PAREDES, FELICIANO | E6: 862440 | F6: 862440 | G6: =E6-F6 -> 0
A7: =A6+1 -> 6 | B7: =IFERROR(INDEX(Hoja1!A:A,MATCH(C7,Hoja1!C:C,0)),"") -> 2653 | C7: 2505036 | D7: =IFERROR(INDEX(Hoja1!B:B,MATCH(C7,Hoja1!C:C,0)),"") -> RUIZ PEREZ, ANGEL DARIO | E7: 991803 | F7: 991803 | G7: =E7-F7 -> 0
A8: =A7+1 -> 7 | B8: =IFERROR(INDEX(Hoja1!A:A,MATCH(C8,Hoja1!C:C,0)),"") -> 3183 | C8: 2974957 | D8: =IFERROR(INDEX(Hoja1!B:B,MATCH(C8,Hoja1!C:C,0)),"") -> ALARCON CHAMORRO, ESTEBAN | E8: 655763 | F8: 0 | G8: =E8-F8 -> 655763
A9: =A8+1 -> 8 | B9: =IFERROR(INDEX(Hoja1!A:A,MATCH(C9,Hoja1!C:C,0)),"") -> 3227 | C9: 4549431 | D9: =IFERROR(INDEX(Hoja1!B:B,MATCH(C9,Hoja1!C:C,0)),"") -> OCAMPOS, CESAR RUBEN | E9: 690659 | F9: 690659 | G9: =E9-F9 -> 0
A10: =A9+1 -> 9 | B10: =IFERROR(INDEX(Hoja1!A:A,MATCH(C10,Hoja1!C:C,0)),"") -> 3228 | C10: 3817655 | D10: =IFERROR(INDEX(Hoja1!B:B,MATCH(C10,Hoja1!C:C,0)),"") -> BENITEZ DUARTE, CLAUDIO | E10: 2068391 | F10: 950000 | G10: =E10-F10 -> 1118391
A11: =A10+1 -> 10 | B11: =IFERROR(INDEX(Hoja1!A:A,MATCH(C11,Hoja1!C:C,0)),"") -> 3467 | C11: 2375969 | D11: =IFERROR(INDEX(Hoja1!B:B,MATCH(C11,Hoja1!C:C,0)),"") -> GARCETE ESPINOLA, ALBERTO | E11: 737945 | F11: 737945 | G11: =E11-F11 -> 0
A12: =A11+1 -> 11 | B12: =IFERROR(INDEX(Hoja1!A:A,MATCH(C12,Hoja1!C:C,0)),"") -> 3484 | C12: 2501889 | D12: =IFERROR(INDEX(Hoja1!B:B,MATCH(C12,Hoja1!C:C,0)),"") -> CANTERO CANO, JORGE RENE | E12: 2542498 | F12: 700000 | G12: =E12-F12 -> 1842498
A13: =A12+1 -> 12 | B13: =IFERROR(INDEX(Hoja1!A:A,MATCH(C13,Hoja1!C:C,0)),"") -> 3518 | C13: 3638094 | D13: =IFERROR(INDEX(Hoja1!B:B,MATCH(C13,Hoja1!C:C,0)),"") -> RUIZ TALAVERA, JORGE | E13: 753938 | F13: 753938 | G13: =E13-F13 -> 0
A14: =A13+1 -> 13 | B14: =IFERROR(INDEX(Hoja1!A:A,MATCH(C14,Hoja1!C:C,0)),"") -> 3554 | C14: 3503958 | D14: =IFERROR(INDEX(Hoja1!B:B,MATCH(C14,Hoja1!C:C,0)),"") -> SALDIVAR SALCEDO, FREDY ANTONIO | E14: 485133 | F14: 485133 | G14: =E14-F14 -> 0
... A59: =A58+1 -> 58 | B59: =IFERROR(INDEX(Hoja1!A:A,MATCH(C59,Hoja1!C:C,0)),"") -> 12802 | C59: 5314835 | D59: =IFERROR(INDEX(Hoja1!B:B,MATCH(C59,Hoja1!C:C,0)),"") -> SOSA VILLASBOA, JOSE SAUL | E59: 872525 | F59: 423000 | G59: =E59-F59 -> 449525
A60: Total General | E60: =SUM(E2:E59) -> 48127775 | F60: =SUM(F2:F59) -> 31787459 | G60: =SUM(G2:G59) -> 16340316

Sheet Unidad 8
A1: N° | B1: N° Socio | C1: N° de CI | D1: Apellido y Nombre | E1: Total Descuentos | F1: Cobrado | G1: Rechazado
A2: 1 | B2: =IFERROR(INDEX(Hoja1!A:A,MATCH(C2,Hoja1!C:C,0)),"") -> 854 | C2: 2005902 | D2: =IFERROR(INDEX(Hoja1!B:B,MATCH(C2,Hoja1!C:C,0)),"") -> OTAZU SANCHEZ, OSCAR ORLANDO | E2: 1572385 | F2: 1572385 | G2: =E2-F2 -> 0
A3: =A2+1 -> 2 | B3: =IFERROR(INDEX(Hoja1!A:A,MATCH(C3,Hoja1!C:C,0)),"") -> 2063 | C3: 3242727 | D3: =IFERROR(INDEX(Hoja1!B:B,MATCH(C3,Hoja1!C:C,0)),"") -> BORDON CABALLERO, INOCENCIO | E3: 1012692 | F3: 1012692 | G3: =E3-F3 -> 0
A4: =A3+1 -> 3 | B4: =IFERROR(INDEX(Hoja1!A:A,MATCH(C4,Hoja1!C:C,0)),"") -> 2918 | C4: 2888719 | D4: =IFERROR(INDEX(Hoja1!B:B,MATCH(C4,Hoja1!C:C,0)),"") -> FRANCO DUARTE, VICTOR APARICIO | E4: 909545 | F4: 0 | G4: =E4-F4 -> 909545
A5: =A4+1 -> 4 | B5: =IFERROR(INDEX(Hoja1!A:A,MATCH(C5,Hoja1!C:C,0)),"") -> 3435 | C5: 3849525 | D5: =IFERROR(INDEX(Hoja1!B:B,MATCH(C5,Hoja1!C:C,0)),"") -> CAÑETE, ABRAHAN | E5: 946830 | F5: 0 | G5: =E5-F5 -> 946830
A6: =A5+1 -> 5 | B6: =IFERROR(INDEX(Hoja1!A:A,MATCH(C6,Hoja1!C:C,0)),"") -> 3615 | C6: 4237987 | D6: =IFERROR(INDEX(Hoja1!B:B,MATCH(C6,Hoja1!C:C,0)),"") -> VILLAMAYOR ESTIGARRIBIA, JOSE | E6: 1285024 | F6: 1285024 | G6: =E6-F6 -> 0
A7: =A6+1 -> 6 | B7: =IFERROR(INDEX(Hoja1!A:A,MATCH(C7,Hoja1!C:C,0)),"") -> 5146 | C7: 3835136 | D7: =IFERROR(INDEX(Hoja1!B:B,MATCH(C7,Hoja1!C:C,0)),"") -> URUNAGA, PEDRO HERNAN | E7: 34000 | F7: 34000 | G7: =E7-F7 -> 0
A8: =A7+1 -> 7 | B8: =IFERROR(INDEX(Hoja1!A:A,MATCH(C8,Hoja1!C:C,0)),"") -> 5360 | C8: 2181109 | D8: =IFERROR(INDEX(Hoja1!B:B,MATCH(C8,Hoja1!C:C,0)),"") -> GONZALEZ ESPINOLA, GENARO OSVALDO | E8: 1739599 | F8: 1739599 | G8: =E8-F8 -> 0
A9: =A8+1 -> 8 | B9: =IFERROR(INDEX(Hoja1!A:A,MATCH(C9,Hoja1!C:C,0)),"") -> 5780 | C9: 4206573 | D9: =IFERROR(INDEX(Hoja1!B:B,MATCH(C9,Hoja1!C:C,0)),"") -> CALVETTI, ALBERTO ANASTACIO | E9: 1175317 | F9: 1151052 | G9: =E9-F9 -> 24265
A10: =A9+1 -> 9 | B10: =IFERROR(INDEX(Hoja1!A:A,MATCH(C10,Hoja1!C:C,0)),"") -> 6055 | C10: 5029175 | D10: =IFERROR(INDEX(Hoja1!B:B,MATCH(C10,Hoja1!C:C,0)),"") -> GAMARRA GONZALEZ, WILSON OSCAR | E10: 757809 | F10: 0 | G10: =E10-F10 -> 757809
A11: =A10+1 -> 10 | B11: =IFERROR(INDEX(Hoja1!A:A,MATCH(C11,Hoja1!C:C,0)),"") -> 6379 | C11: 5206179 | D11: =IFERROR(INDEX(Hoja1!B:B,MATCH(C11,Hoja1!C:C,0)),"") -> GALEANO FRUTOS, ELIEZER | E11: 2248009 | F11: 2071299 | G11: =E11-F11 -> 176710
A12: =A11+1 -> 11 | B12: =IFERROR(INDEX(Hoja1!A:A,MATCH(C12,Hoja1!C:C,0)),"") -> 7478 | C12: 4320227 | D12: =IFERROR(INDEX(Hoja1!B:B,MATCH(C12,Hoja1!C:C,0)),"") -> CANDIA ORTEGA, CESAR GABRIEL | E12: 54000 | F12: 54000 | G12: =E12-F12 -> 0
A13: =A12+1 -> 12 | B13: =IFERROR(INDEX(Hoja1!A:A,MATCH(C13,Hoja1!C:C,0)),"") -> 7762 | C13: 3797644 | D13: =IFERROR(INDEX(Hoja1!B:B,MATCH(C13,Hoja1!C:C,0)),"") -> SALA COLMAN, JOEL DAVID | E13: 1006435 | F13: 1006435 | G13: =E13-F13 -> 0
A14: =A13+1 -> 13 | B14: =IFERROR(INDEX(Hoja1!A:A,MATCH(C14,Hoja1!C:C,0)),"") -> 7987 | C14: 5304031 | D14: =IFERROR(INDEX(Hoja1!B:B,MATCH(C14,Hoja1!C:C,0)),"") -> DIAZ, PABLO DAMIAN | E14: 862440 | F14: 279442 | G14: =E14-F14 -> 582998
... A29: =A28+1 -> 28 | B29: =IFERROR(INDEX(Hoja1!A:A,MATCH(C29,Hoja1!C:C,0)),"") -> 13540 | C29: 5676898 | D29: =IFERROR(INDEX(Hoja1!B:B,MATCH(C29,Hoja1!C:C,0)),"") -> ESCURRA SANCHEZ, ANGEL JESUS | E29: 547216 | F29: 547216 | G29: =E29-F29 -> 0
A30: Total General | E30: =SUM(E2:E29) -> 23833550 | F30: =SUM(F2:F29) -> 14676502 | G30: =SUM(G2:G29) -> 9157048

Sheet Unidad 9
A1: N° | B1: N° Socio | C1: N° de CI | D1: Apellido y Nombre | E1: Total Descuentos | F1: Cobrado | G1: Rechazado
A2: 1 | B2: =IFERROR(INDEX(Hoja1!A:A,MATCH(C2,Hoja1!C:C,0)),"") -> 788 | C2: 3613039 | D2: =IFERROR(INDEX(Hoja1!B:B,MATCH(C2,Hoja1!C:C,0)),"") -> ARAUJO ROLON, SELSO | E2: 34000 | F2: 34000 | G2: =E2-F2 -> 0
A3: =A2+1 -> 2 | B3: =IFERROR(INDEX(Hoja1!A:A,MATCH(C3,Hoja1!C:C,0)),"") -> 1597 | C3: 1331138 | D3: =IFERROR(INDEX(Hoja1!B:B,MATCH(C3,Hoja1!C:C,0)),"") -> FERREIRA AQUINO, MARIANA | E3: 309875 | F3: 309875 | G3: =E3-F3 -> 0
A4: =A3+1 -> 3 | B4: =IFERROR(INDEX(Hoja1!A:A,MATCH(C4,Hoja1!C:C,0)),"") -> 1691 | C4: 1131607 | D4: =IFERROR(INDEX(Hoja1!B:B,MATCH(C4,Hoja1!C:C,0)),"") -> MORALES MAYEREGGER, ELSA | E4: 1097651 | F4: 630000 | G4: =E4-F4 -> 467651
A5: =A4+1 -> 4 | B5: =IFERROR(INDEX(Hoja1!A:A,MATCH(C5,Hoja1!C:C,0)),"") -> 1738 | C5: 322163 | D5: =IFERROR(INDEX(Hoja1!B:B,MATCH(C5,Hoja1!C:C,0)),"") -> AGUILERA VDA DE KRONE, RAMONITA | E5: 30000 | F5: 0 | G5: =E5-F5 -> 30000
A6: =A5+1 -> 5 | B6: =IFERROR(INDEX(Hoja1!A:A,MATCH(C6,Hoja1!C:C,0)),"") -> 9990 | C6: 5319821 | D6: =IFERROR(INDEX(Hoja1!B:B,MATCH(C6,Hoja1!C:C,0)),"") -> ARAUJO RIQUELME, CESAR DAVID | E6: 550048 | F6: 550048 | G6: =E6-F6 -> 0
A7: =A6+1 -> 6 | B7: =IFERROR(INDEX(Hoja1!A:A,MATCH(C7,Hoja1!C:C,0)),"") -> 13222 | C7: 4879847 | D7: =IFERROR(INDEX(Hoja1!B:B,MATCH(C7,Hoja1!C:C,0)),"") -> BENITEZ GIMENEZ, FRANCISCO DAVID | E7: 34000 | F7: 34000 | G7: =E7-F7 -> 0
A8: Total General | E8: =SUM(E2:E7) -> 2055574 | F8: =SUM(F2:F7) -> 1557923 | G8: =SUM(G2:G7) -> 497651

Sheet Unidad 10
A1: N° | B1: N° Socio | C1: N° de CI | D1: Apellido y Nombre | E1: Total Descuentos | F1: Cobrado | G1: Rechazado
A2: 1 | B2: =IFERROR(INDEX(Hoja1!A:A,MATCH(C2,Hoja1!C:C,0)),"") -> 22 | C2: 442422 | D2: =IFERROR(INDEX(Hoja1!B:B,MATCH(C2,Hoja1!C:C,0)),"") -> GONZALEZ MARTINEZ, VIRGILIO | E2: 1650562 | F2: 1650562 | G2: =E2-F2 -> 0
A3: =A2+1 -> 2 | B3: =IFERROR(INDEX(Hoja1!A:A,MATCH(C3,Hoja1!C:C,0)),"") -> 29 | C3: 367112 | D3: =IFERROR(INDEX(Hoja1!B:B,MATCH(C3,Hoja1!C:C,0)),"") -> ESQUIVEL CABALLERO, RAMON RICARDO | E3: 5301496 | F3: 5301496 | G3: =E3-F3 -> 0
A4: =A3+1 -> 3 | B4: =IFERROR(INDEX(Hoja1!A:A,MATCH(C4,Hoja1!C:C,0)),"") -> 58 | C4: 666054 | D4: =IFERROR(INDEX(Hoja1!B:B,MATCH(C4,Hoja1!C:C,0)),"") -> LEIVA LOPEZ, JORGE SILVINO | E4: 2979363 | F4: 2979363 | G4: =E4-F4 -> 0
A5: =A4+1 -> 4 | B5: =IFERROR(INDEX(Hoja1!A:A,MATCH(C5,Hoja1!C:C,0)),"") -> 60 | C5: 653644 | D5: =IFERROR(INDEX(Hoja1!B:B,MATCH(C5,Hoja1!C:C,0)),"") -> LOPEZ QUINTANA, CARLOS SISINIO | E5: 34000 | F5: 34000 | G5: =E5-F5 -> 0
A6: =A5+1 -> 5 | B6: =IFERROR(INDEX(Hoja1!A:A,MATCH(C6,Hoja1!C:C,0)),"") -> 74 | C6: 1215427 | D6: =IFERROR(INDEX(Hoja1!B:B,MATCH(C6,Hoja1!C:C,0)),"") -> CABRERA GONZALEZ, SANTIAGO SABINO | E6: 2761318 | F6: 2761318 | G6: =E6-F6 -> 0
A7: =A6+1 -> 6 | B7: =IFERROR(INDEX(Hoja1!A:A,MATCH(C7,Hoja1!C:C,0)),"") -> 111 | C7: 1067952 | D7: =IFERROR(INDEX(Hoja1!B:B,MATCH(C7,Hoja1!C:C,0)),"") -> ACOSTA AGUIRRE, JAVIER | E7: 2310129 | F7: 2310129 | G7: =E7-F7 -> 0
A8: =A7+1 -> 7 | B8: =IFERROR(INDEX(Hoja1!A:A,MATCH(C8,Hoja1!C:C,0)),"") -> 127 | C8: 527490 | D8: =IFERROR(INDEX(Hoja1!B:B,MATCH(C8,Hoja1!C:C,0)),"") -> WAGENBACH, ENRIQUE WERNER | E8: 34000 | F8: 34000 | G8: =E8-F8 -> 0
A9: =A8+1 -> 8 | B9: =IFERROR(INDEX(Hoja1!A:A,MATCH(C9,Hoja1!C:C,0)),"") -> 160 | C9: 661853 | D9: =IFERROR(INDEX(Hoja1!B:B,MATCH(C9,Hoja1!C:C,0)),"") -> MEDINA, FELIX VALOY | E9: 34000 | F9: 34000 | G9: =E9-F9 -> 0
A10: =A9+1 -> 9 | B10: =IFERROR(INDEX(Hoja1!A:A,MATCH(C10,Hoja1!C:C,0)),"") -> 165 | C10: 483822 | D10: =IFERROR(INDEX(Hoja1!B:B,MATCH(C10,Hoja1!C:C,0)),"") -> ESCOBAR BENEGAS, WILFRIDO | E10: 34000 | F10: 34000 | G10: =E10-F10 -> 0
A11: =A10+1 -> 10 | B11: =IFERROR(INDEX(Hoja1!A:A,MATCH(C11,Hoja1!C:C,0)),"") -> 172 | C11: 624491 | D11: =IFERROR(INDEX(Hoja1!B:B,MATCH(C11,Hoja1!C:C,0)),"") -> ROTELA, RUBEN MOISES | E11: 1784975 | F11: 1784975 | G11: =E11-F11 -> 0
A12: =A11+1 -> 11 | B12: =IFERROR(INDEX(Hoja1!A:A,MATCH(C12,Hoja1!C:C,0)),"") -> 186 | C12: 908131 | D12: =IFERROR(INDEX(Hoja1!B:B,MATCH(C12,Hoja1!C:C,0)),"") -> VELAZQUEZ VELAZQUEZ, PABLO | E12: 1715109 | F12: 1715109 | G12: =E12-F12 -> 0
A13: =A12+1 -> 12 | B13: =IFERROR(INDEX(Hoja1!A:A,MATCH(C13,Hoja1!C:C,0)),"") -> 191 | C13: 299663 | D13: =IFERROR(INDEX(Hoja1!B:B,MATCH(C13,Hoja1!C:C,0)),"") -> FLORENTIN RIVAROLA, ARNALDO RAMON | E13: 1196180 | F13: 1196180 | G13: =E13-F13 -> 0
A14: =A13+1 -> 13 | B14: =IFERROR(INDEX(Hoja1!A:A,MATCH(C14,Hoja1!C:C,0)),"") -> 192 | C14: 366032 | D14: =IFERROR(INDEX(Hoja1!B:B,MATCH(C14,Hoja1!C:C,0)),"") -> RODRIGUEZ JARA, ARSENIO | E14: 34000 | F14: 34000 | G14: =E14-F14 -> 0
... A138: =A137+1 -> 137 | B138: =IFERROR(INDEX(Hoja1!A:A,MATCH(C138,Hoja1!C:C,0)),"") -> 13379 | C138: 1836302 | D138: =IFERROR(INDEX(Hoja1!B:B,MATCH(C138,Hoja1!C:C,0)),"") -> BENTO OCAMPOS, RAMON | E138: 355150 | F138: 355150 | G138: =E138-F138 -> 0
A139: Total General | E139: =SUM(E2:E138) -> 164900187 | F139: =SUM(F2:F138) -> 151921163 | G139: =SUM(G2:G138) -> 12979024

Sheet Unidad 12
A1: N° | B1: N° Socio | C1: N° de CI | D1: Apellido y Nombre | E1: Total Descuentos | F1: Cobrado | G1: Rechazado
A2: 1 | B2: =IFERROR(INDEX(Hoja1!A:A,MATCH(C2,Hoja1!C:C,0)),"") -> 3892 | C2: 4361990 | D2: =IFERROR(INDEX(Hoja1!B:B,MATCH(C2,Hoja1!C:C,0)),"") -> ESCOBAR MOLINAS, MIGUEL ANGEL | E2: 640589 | F2: 640589 | G2: =E2-F2 -> 0
A3: =A2+1 -> 2 | B3: =IFERROR(INDEX(Hoja1!A:A,MATCH(C3,Hoja1!C:C,0)),"") -> 4676 | C3: 6057211 | D3: =IFERROR(INDEX(Hoja1!B:B,MATCH(C3,Hoja1!C:C,0)),"") -> MARTINEZ MENDOZA, RAMON | E3: 34000 | F3: 34000 | G3: =E3-F3 -> 0
A4: =A3+1 -> 3 | B4: =IFERROR(INDEX(Hoja1!A:A,MATCH(C4,Hoja1!C:C,0)),"") -> 5465 | C4: 2535413 | D4: =IFERROR(INDEX(Hoja1!B:B,MATCH(C4,Hoja1!C:C,0)),"") -> DIAZ OLMEDO, FERNANDO RUBEN | E4: 54000 | F4: 54000 | G4: =E4-F4 -> 0
A5: =A4+1 -> 4 | B5: =IFERROR(INDEX(Hoja1!A:A,MATCH(C5,Hoja1!C:C,0)),"") -> 5912 | C5: 3691461 | D5: =IFERROR(INDEX(Hoja1!B:B,MATCH(C5,Hoja1!C:C,0)),"") -> ORTEGA SERVIAN, TERESA | E5: 808453 | F5: 808453 | G5: =E5-F5 -> 0
A6: =A5+1 -> 5 | B6: =IFERROR(INDEX(Hoja1!A:A,MATCH(C6,Hoja1!C:C,0)),"") -> 8060 | C6: 6893977 | D6: =IFERROR(INDEX(Hoja1!B:B,MATCH(C6,Hoja1!C:C,0)),"") -> PEREZ TELLEZ, JOSE EDUARDO | E6: 868016 | F6: 868016 | G6: =E6-F6 -> 0
A7: =A6+1 -> 6 | B7: =IFERROR(INDEX(Hoja1!A:A,MATCH(C7,Hoja1!C:C,0)),"") -> 10975 | C7: 3591249 | D7: =IFERROR(INDEX(Hoja1!B:B,MATCH(C7,Hoja1!C:C,0)),"") -> FLORENCIAÑEZ GIBBONS, JORGE ELIAS | E7: 34000 | F7: 34000 | G7: =E7-F7 -> 0
E8: =SUM(E2:E7) -> 2439058 | F8: =SUM(F2:F7) -> 2439058 | G8: =SUM(G2:G7) -> 0

Sheet Unidad 13
A1: N° | B1: N° Socio | C1: N° de CI | D1: Apellido y Nombre | E1: Total Descuentos | F1: Cobrado | G1: Rechazado
A2: 1 | B2: =IFERROR(INDEX(Hoja1!A:A,MATCH(C2,Hoja1!C:C,0)),"") -> 541 | C2: 2486052 | D2: =IFERROR(INDEX(Hoja1!B:B,MATCH(C2,Hoja1!C:C,0)),"") -> MORAL CENTURION, VICTOR ALBERTO | E2: 512616 | F2: 512616 | G2: =E2-F2 -> 0
A3: =A2+1 -> 2 | B3: =IFERROR(INDEX(Hoja1!A:A,MATCH(C3,Hoja1!C:C,0)),"") -> 2591 | C3: 1944826 | D3: =IFERROR(INDEX(Hoja1!B:B,MATCH(C3,Hoja1!C:C,0)),"") -> MARTINEZ ORUE, GUSTAVO CARLOS | E3: 3452630 | F3: 3452630 | G3: =E3-F3 -> 0
A4: =A3+1 -> 3 | B4: =IFERROR(INDEX(Hoja1!A:A,MATCH(C4,Hoja1!C:C,0)),"") -> 2871 | C4: 2288976 | D4: =IFERROR(INDEX(Hoja1!B:B,MATCH(C4,Hoja1!C:C,0)),"") -> ARRIOLA SALDIVAR, BRUNO | E4: 690659 | F4: 690659 | G4: =E4-F4 -> 0
A5: =A4+1 -> 4 | B5: =IFERROR(INDEX(Hoja1!A:A,MATCH(C5,Hoja1!C:C,0)),"") -> 3578 | C5: 781275 | D5: =IFERROR(INDEX(Hoja1!B:B,MATCH(C5,Hoja1!C:C,0)),"") -> ROMERO CAÑETE, MARTIN | E5: 611006 | F5: 591600 | G5: =E5-F5 -> 19406
A6: =A5+1 -> 5 | B6: =IFERROR(INDEX(Hoja1!A:A,MATCH(C6,Hoja1!C:C,0)),"") -> 3740 | C6: 2265346 | D6: =IFERROR(INDEX(Hoja1!B:B,MATCH(C6,Hoja1!C:C,0)),"") -> MARTINEZ MEZA, EDGAR AUGUSTO | E6: 54000 | F6: 54000 | G6: =E6-F6 -> 0
A7: =A6+1 -> 6 | B7: =IFERROR(INDEX(Hoja1!A:A,MATCH(C7,Hoja1!C:C,0)),"") -> 5140 | C7: 1503220 | D7: =IFERROR(INDEX(Hoja1!B:B,MATCH(C7,Hoja1!C:C,0)),"") -> ORTIZ ROJAS, BLAS ANGEL | E7: 625282 | F7: 625282 | G7: =E7-F7 -> 0
A8: =A7+1 -> 7 | B8: =IFERROR(INDEX(Hoja1!A:A,MATCH(C8,Hoja1!C:C,0)),"") -> 6758 | C8: 3977133 | D8: =IFERROR(INDEX(Hoja1!B:B,MATCH(C8,Hoja1!C:C,0)),"") -> RIOS PORTILLO, ADRIAN | E8: 327608 | F8: 327608 | G8: =E8-F8 -> 0
A9: =A8+1 -> 8 | B9: =IFERROR(INDEX(Hoja1!A:A,MATCH(C9,Hoja1!C:C,0)),"") -> 12509 | C9: 5484684 | D9: =IFERROR(INDEX(Hoja1!B:B,MATCH(C9,Hoja1!C:C,0)),"") -> LOPEZ, BRAULIO FRANCISCO | E9: 54000 | F9: 54000 | G9: =E9-F9 -> 0
E10: =SUM(E2:E9) -> 6327801 | F10: =SUM(F2:F9) -> 6308395 | G10: =SUM(G2:G9) -> 19406

Sheet Unidad 14
A1: N° | B1: N° Socio | C1: N° de CI | D1: Apellido y Nombre | E1: Total Descuentos | F1: Cobrado | G1: Rechazado
A2: 1 | B2: =IFERROR(INDEX(Hoja1!A:A,MATCH(C2,Hoja1!C:C,0)),"") -> 114 | C2: 1891836 | D2: =IFERROR(INDEX(Hoja1!B:B,MATCH(C2,Hoja1!C:C,0)),"") -> ARRUA ALMADA, EDUARDO MIGUEL | E2: 34000 | F2: 0 | G2: =E2-F2 -> 34000
A3: =A2+1 -> 2 | B3: =IFERROR(INDEX(Hoja1!A:A,MATCH(C3,Hoja1!C:C,0)),"") -> 445 | C3: 2329524 | D3: =IFERROR(INDEX(Hoja1!B:B,MATCH(C3,Hoja1!C:C,0)),"") -> BENITEZ BORDON, JOEL LUCIANO | E3: 2200543 | F3: 0 | G3: =E3-F3 -> 2200543
A4: =A3+1 -> 3 | B4: =IFERROR(INDEX(Hoja1!A:A,MATCH(C4,Hoja1!C:C,0)),"") -> 555 | C4: 2381331 | D4: =IFERROR(INDEX(Hoja1!B:B,MATCH(C4,Hoja1!C:C,0)),"") -> AMARILLA VENIALGO, BLAS | E4: 54000 | F4: 0 | G4: =E4-F4 -> 54000
A5: =A4+1 -> 4 | B5: =IFERROR(INDEX(Hoja1!A:A,MATCH(C5,Hoja1!C:C,0)),"") -> 807 | C5: 1586068 | D5: =IFERROR(INDEX(Hoja1!B:B,MATCH(C5,Hoja1!C:C,0)),"") -> RAMIREZ ROLON, JULIO CESAR | E5: 4891060 | F5: 0 | G5: =E5-F5 -> 4891060
A6: =A5+1 -> 5 | B6: =IFERROR(INDEX(Hoja1!A:A,MATCH(C6,Hoja1!C:C,0)),"") -> 855 | C6: 1808067 | D6: =IFERROR(INDEX(Hoja1!B:B,MATCH(C6,Hoja1!C:C,0)),"") -> MEDINA MARTINEZ, JOSE FELIX | E6: 360302 | F6: 360302 | G6: =E6-F6 -> 0
A7: =A6+1 -> 6 | B7: =IFERROR(INDEX(Hoja1!A:A,MATCH(C7,Hoja1!C:C,0)),"") -> 891 | C7: 847774 | D7: =IFERROR(INDEX(Hoja1!B:B,MATCH(C7,Hoja1!C:C,0)),"") -> BENITEZ BAEZ, JUAN VICENTE | E7: 1924211 | F7: 0 | G7: =E7-F7 -> 1924211
A8: =A7+1 -> 7 | B8: =IFERROR(INDEX(Hoja1!A:A,MATCH(C8,Hoja1!C:C,0)),"") -> 934 | C8: 3836919 | D8: =IFERROR(INDEX(Hoja1!B:B,MATCH(C8,Hoja1!C:C,0)),"") -> LARROZA BRITEZ, CORNELIO RAMON | E8: 3392206 | F8: 3231989 | G8: =E8-F8 -> 160217
A9: =A8+1 -> 8 | B9: =IFERROR(INDEX(Hoja1!A:A,MATCH(C9,Hoja1!C:C,0)),"") -> 1050 | C9: 1231011 | D9: =IFERROR(INDEX(Hoja1!B:B,MATCH(C9,Hoja1!C:C,0)),"") -> ORTIZ ESPINOZA, NELSON AUGUSTO | E9: 34000 | F9: 34000 | G9: =E9-F9 -> 0
A10: =A9+1 -> 9 | B10: =IFERROR(INDEX(Hoja1!A:A,MATCH(C10,Hoja1!C:C,0)),"") -> 1538 | C10: 2448712 | D10: =IFERROR(INDEX(Hoja1!B:B,MATCH(C10,Hoja1!C:C,0)),"") -> AMARILLA FLEITAS, HECTOR DANIEL | E10: 184000 | F10: 0 | G10: =E10-F10 -> 184000
A11: =A10+1 -> 10 | B11: =IFERROR(INDEX(Hoja1!A:A,MATCH(C11,Hoja1!C:C,0)),"") -> 1786 | C11: 3814794 | D11: =IFERROR(INDEX(Hoja1!B:B,MATCH(C11,Hoja1!C:C,0)),"") -> DELGADO MONGES, ADRIAN | E11: 134000 | F11: 134000 | G11: =E11-F11 -> 0
A12: =A11+1 -> 11 | B12: =IFERROR(INDEX(Hoja1!A:A,MATCH(C12,Hoja1!C:C,0)),"") -> 1968 | C12: 4009839 | D12: =IFERROR(INDEX(Hoja1!B:B,MATCH(C12,Hoja1!C:C,0)),"") -> TORRES ESPINOLA, LUIS ALBERTO | E12: 1259323 | F12: 1259323 | G12: =E12-F12 -> 0
A13: =A12+1 -> 12 | B13: =IFERROR(INDEX(Hoja1!A:A,MATCH(C13,Hoja1!C:C,0)),"") -> 1970 | C13: 4382994 | D13: =IFERROR(INDEX(Hoja1!B:B,MATCH(C13,Hoja1!C:C,0)),"") -> BAREIRO RIVAS, ADOLFO BENIGNO | E13: 803344 | F13: 803344 | G13: =E13-F13 -> 0
A14: =A13+1 -> 13 | B14: =IFERROR(INDEX(Hoja1!A:A,MATCH(C14,Hoja1!C:C,0)),"") -> 2005 | C14: 2201150 | D14: =IFERROR(INDEX(Hoja1!B:B,MATCH(C14,Hoja1!C:C,0)),"") -> RAMIREZ MARIN, JORGE ANTONIO | E14: 412912 | F14: 412912 | G14: =E14-F14 -> 0
... A163: =A162+1 -> 162 | B163: =IFERROR(INDEX(Hoja1!A:A,MATCH(C163,Hoja1!C:C,0)),"") -> 13424 | C163: 6713212 | D163: =IFERROR(INDEX(Hoja1!B:B,MATCH(C163,Hoja1!C:C,0)),"") -> ROMERO ARECO, DIEGO IVAN | E163: 894161 | F163: 894161 | G163: =E163-F163 -> 0
A164: Total General | E164: =SUM(E2:E163) -> 154670404 | F164: =SUM(F2:F163) -> 102183138 | G164: =SUM(G2:G163) -> 52487266

Sheet Unidad 15
A1: N° | B1: N° Socio | C1: N° de CI | D1: Apellido y Nombre | E1: Total Descuentos | F1: Cobrado | G1: Rechazado
A2: 1 | B2: =IFERROR(INDEX(Hoja1!A:A,MATCH(C2,Hoja1!C:C,0)),"") -> 2637 | C2: 4331841 | D2: =IFERROR(INDEX(Hoja1!B:B,MATCH(C2,Hoja1!C:C,0)),"") -> CACERES LLANES, FAUSTINO | E2: 382330 | F2: 382330 | G2: =E2-F2 -> 0
A3: 2 | B3: =IFERROR(INDEX(Hoja1!A:A,MATCH(C3,Hoja1!C:C,0)),"") -> 10352 | C3: 4676026 | D3: =IFERROR(INDEX(Hoja1!B:B,MATCH(C3,Hoja1!C:C,0)),"") -> GONZALEZ CHAMORRO, NELSON ARTURO | E3: 34000 | F3: 34000 | G3: =E3-F3 -> 0
A4: Total General | E4: =SUM(E2:E3) -> 416330 | F4: =SUM(F2:F3) -> 416330 | G4: =SUM(G2:G3) -> 0

Sheet Unidad 17
A1: N° | B1: N° Socio | C1: N° de CI | D1: Apellido y Nombre | E1: Total Descuentos | F1: Cobrado | G1: Rechazado
A2: 1 | B2: =IFERROR(INDEX(Hoja1!A:A,MATCH(C2,Hoja1!C:C,0)),"") -> 3462 | C2: 3523504 | D2: =IFERROR(INDEX(Hoja1!B:B,MATCH(C2,Hoja1!C:C,0)),"") -> AVALOS RIQUELME, HUGO FRANCISCO | E2: 471773 | F2: 471773 | G2: =E2-F2 -> 0
A3: 2 | B3: =IFERROR(INDEX(Hoja1!A:A,MATCH(C3,Hoja1!C:C,0)),"") -> 6629 | C3: 4705386 | D3: =IFERROR(INDEX(Hoja1!B:B,MATCH(C3,Hoja1!C:C,0)),"") -> ARCE AVALOS, CRISTHIAN BIENVENIDO | E3: 664395 | F3: 664395 | G3: =E3-F3 -> 0
A4: 3 | B4: =IFERROR(INDEX(Hoja1!A:A,MATCH(C4,Hoja1!C:C,0)),"") -> 9360 | C4: 1243523 | D4: =IFERROR(INDEX(Hoja1!B:B,MATCH(C4,Hoja1!C:C,0)),"") -> GIMENEZ BAVERA, ARNALDO MANUEL | E4: 316575 | F4: 316575 | G4: =E4-F4 -> 0
A5: 4 | B5: =IFERROR(INDEX(Hoja1!A:A,MATCH(C5,Hoja1!C:C,0)),"") -> 11326 | C5: 6675882 | D5: =IFERROR(INDEX(Hoja1!B:B,MATCH(C5,Hoja1!C:C,0)),"") -> RIVEROS LUGO, ROBERT JUAN | E5: 34000 | F5: 34000 | G5: =E5-F5 -> 0
A6: Total General | E6: =SUM(E2:E5) -> 1486743 | F6: =SUM(F2:F5) -> 1486743 | G6: =SUM(G2:G5) -> 0

Sheet Unidad 18
A1: N° | B1: N° Socio | C1: N° de CI | D1: Apellido y Nombre | E1: Total Descuentos | F1: Cobrado | G1: Rechazado
A2: 1 | B2: =IFERROR(INDEX(Hoja1!A:A,MATCH(C2,Hoja1!C:C,0)),"") -> 1111 | C2: 2962752 | D2: =IFERROR(INDEX(Hoja1!B:B,MATCH(C2,Hoja1!C:C,0)),"") -> FARIÑA RUIZ, ARIEL ULISES | E2: 34000 | F2: 34000 | G2: =E2-F2 -> 0
A3: =A2+1 -> 2 | B3: =IFERROR(INDEX(Hoja1!A:A,MATCH(C3,Hoja1!C:C,0)),"") -> 4516 | C3: 3447044 | D3: =IFERROR(INDEX(Hoja1!B:B,MATCH(C3,Hoja1!C:C,0)),"") -> VALDEZ VELAZQUEZ, DAHIANA ELIZABETH | E3: 1590233 | F3: 1590233 | G3: =E3-F3 -> 0
A4: =A3+1 -> 3 | B4: =IFERROR(INDEX(Hoja1!A:A,MATCH(C4,Hoja1!C:C,0)),"") -> 4617 | C4: 1901424 | D4: =IFERROR(INDEX(Hoja1!B:B,MATCH(C4,Hoja1!C:C,0)),"") -> MARTINEZ ALVARENGA, VICTOR MAYO | E4: 1978973 | F4: 0 | G4: =E4-F4 -> 1978973
A5: =A4+1 -> 4 | B5: =IFERROR(INDEX(Hoja1!A:A,MATCH(C5,Hoja1!C:C,0)),"") -> 4679 | C5: 2484108 | D5: =IFERROR(INDEX(Hoja1!B:B,MATCH(C5,Hoja1!C:C,0)),"") -> CAPDEVILA FRUTOS, RAFAEL | E5: 717948 | F5: 717948 | G5: =E5-F5 -> 0
A6: =A5+1 -> 5 | B6: =IFERROR(INDEX(Hoja1!A:A,MATCH(C6,Hoja1!C:C,0)),"") -> 5378 | C6: 4618749 | D6: =IFERROR(INDEX(Hoja1!B:B,MATCH(C6,Hoja1!C:C,0)),"") -> ZARACHO ROMAN, JUSTO ISMAEL | E6: 1081216 | F6: 1081216 | G6: =E6-F6 -> 0
A7: =A6+1 -> 6 | B7: =IFERROR(INDEX(Hoja1!A:A,MATCH(C7,Hoja1!C:C,0)),"") -> 6086 | C7: 5029667 | D7: =IFERROR(INDEX(Hoja1!B:B,MATCH(C7,Hoja1!C:C,0)),"") -> GAMARRA ARANDA, ANDREA SOLEDAD | E7: 334000 | F7: 334000 | G7: =E7-F7 -> 0
A8: =A7+1 -> 7 | B8: =IFERROR(INDEX(Hoja1!A:A,MATCH(C8,Hoja1!C:C,0)),"") -> 6097 | C8: 4546262 | D8: =IFERROR(INDEX(Hoja1!B:B,MATCH(C8,Hoja1!C:C,0)),"") -> AQUINO CACERES, VIDAL MATIAS | E8: 883910 | F8: 883910 | G8: =E8-F8 -> 0
A9: =A8+1 -> 8 | B9: =IFERROR(INDEX(Hoja1!A:A,MATCH(C9,Hoja1!C:C,0)),"") -> 6737 | C9: 4093766 | D9: =IFERROR(INDEX(Hoja1!B:B,MATCH(C9,Hoja1!C:C,0)),"") -> BAREIRO VERA, LUCAS NICOLAS | E9: 1287037 | F9: 1287037 | G9: =E9-F9 -> 0
A10: =A9+1 -> 9 | B10: =IFERROR(INDEX(Hoja1!A:A,MATCH(C10,Hoja1!C:C,0)),"") -> 7773 | C10: 4299668 | D10: =IFERROR(INDEX(Hoja1!B:B,MATCH(C10,Hoja1!C:C,0)),"") -> ROMERO ROMERO, JUNIOR ENMANUEL | E10: 507288 | F10: 0 | G10: =E10-F10 -> 507288
A11: =A10+1 -> 10 | B11: =IFERROR(INDEX(Hoja1!A:A,MATCH(C11,Hoja1!C:C,0)),"") -> 10242 | C11: 4550940 | D11: =IFERROR(INDEX(Hoja1!B:B,MATCH(C11,Hoja1!C:C,0)),"") -> DOMINGUEZ SANGUINETTI, TEODORO | E11: 1746887 | F11: 0 | G11: =E11-F11 -> 1746887
A12: Total General | E12: =SUM(E2:E11) -> 10161492 | F12: =SUM(F2:F11) -> 5928344 | G12: =SUM(G2:G11) -> 4233148

Sheet Unidad 20
A1: N° | B1: N° Socio | C1: N° de CI | D1: Apellido y Nombre | E1: Total Descuentos | F1: Cobrado | G1: Rechazado
A2: 1 | B2: =IFERROR(INDEX(Hoja1!A:A,MATCH(C2,Hoja1!C:C,0)),"") -> 561 | C2: 2573093 | D2: =IFERROR(INDEX(Hoja1!B:B,MATCH(C2,Hoja1!C:C,0)),"") -> VENIALGO GIMENEZ, LUIS ALBERTO | E2: 1118094 | F2: 1118094 | G2: =E2-F2 -> 0
A3: 2 | B3: =IFERROR(INDEX(Hoja1!A:A,MATCH(C3,Hoja1!C:C,0)),"") -> 7656 | C3: 3754155 | D3: =IFERROR(INDEX(Hoja1!B:B,MATCH(C3,Hoja1!C:C,0)),"") -> ACOSTA MARTINEZ, DARIO ANDRES | E3: 1534000 | F3: 1534000 | G3: =E3-F3 -> 0
A4: 3 | B4: =IFERROR(INDEX(Hoja1!A:A,MATCH(C4,Hoja1!C:C,0)),"") -> 9531 | C4: 4392567 | D4: =IFERROR(INDEX(Hoja1!B:B,MATCH(C4,Hoja1!C:C,0)),"") -> ORIHUELA GABE, JONATAN ARIEL | E4: 34000 | F4: 34000 | G4: =E4-F4 -> 0
A5: 4 | B5: =IFERROR(INDEX(Hoja1!A:A,MATCH(C5,Hoja1!C:C,0)),"") -> 12602 | C5: 6157776 | D5: =IFERROR(INDEX(Hoja1!B:B,MATCH(C5,Hoja1!C:C,0)),"") -> ATIRILLO MATORO, NEIDA TERESA | E5: 334805 | F5: 0 | G5: =E5-F5 -> 334805
A6: Total General | E6: =SUM(E2:E5) -> 3020899 | F6: =SUM(F2:F5) -> 2686094 | G6: =SUM(G2:G5) -> 334805

Sheet Unidad 22
A1: N° | B1: N° Socio | C1: N° de CI | D1: Apellido y Nombre | E1: Total Descuentos | F1: Cobrado | G1: Rechazado
A2: 1 | B2: =IFERROR(INDEX(Hoja1!A:A,MATCH(C2,Hoja1!C:C,0)),"") -> 6617 | C2: 2343661 | D2: =IFERROR(INDEX(Hoja1!B:B,MATCH(C2,Hoja1!C:C,0)),"") -> GARCIA BRITEZ, JUAN MANUEL | E2: 764158 | F2: 764158 | G2: =E2-F2 -> 0
A3: 2 | B3: =IFERROR(INDEX(Hoja1!A:A,MATCH(C3,Hoja1!C:C,0)),"") -> 12562 | C3: 4715684 | D3: =IFERROR(INDEX(Hoja1!B:B,MATCH(C3,Hoja1!C:C,0)),"") -> DUARTE LEGUIZAMON, LUIS FERNANDO | E3: 313857 | F3: 0 | G3: =E3-F3 -> 313857
A4: Total General | E4: =SUM(E2:E3) -> 1078015 | F4: =SUM(F2:F3) -> 764158 | G4: =SUM(G2:G3) -> 313857

Sheet Unidad 23
A1: N° | B1: N° Socio | C1: N° de CI | D1: Apellido y Nombre | E1: Total Descuentos | F1: Cobrado | G1: Rechazado
A2: 1 | B2: 527 | C2: 1787036 | D2: MELGAREJO GIMENEZ, FAUSTO | E2: 34000 | F2: 34000 | G2: 0
A3: 2 | B3: 641 | C3: 2291128 | D3: MENDOZA FRETES, MARCOS ARTURO | E3: 3098328 | F3: 3098328 | G3: 0
A4: 3 | B4: 672 | C4: 2101801 | D4: FIGUEREDO GUILLEN, RAMON FABIAN | E4: 1527029 | F4: 1527029 | G4: 0
A5: 4 | B5: 702 | C5: 2363898 | D5: OJEDA SALDIVAR, JOSE CLAUDELINO | E5: 34000 | F5: 34000 | G5: 0
A6: 5 | B6: 809 | C6: 1729610 | D6: CABRERA RODRIGUEZ, ALBERTO VICENTE | E6: 4069148 | F6: 1118383 | G6: 2950765
A7: 6 | B7: 981 | C7: 2968414 | D7: VILLALBA AQUINO, DIOSNEL | E7: 3408290 | F7: 3408290 | G7: 0
A8: 7 | B8: 1104 | C8: 2227533 | D8: GIMENEZ VILLAMAYOR, PABLO EBELIO | E8: 34000 | F8: 34000 | G8: 0
A9: 8 | B9: 1108 | C9: 3033998 | D9: FLEYTAS ZARATE, MAURICIO RAMON | E9: 2459370 | F9: 1679198 | G9: 780172
A10: 9 | B10: 1139 | C10: 1880682 | D10: SANTANDER CABRERA, LIDIA MARCELINA | E10: 1624909 | F10: 425094 | G10: 1199815
A11: 10 | B11: 1151 | C11: 3398180 | D11: IBA¥EZ SILVA, JORGE LUIS ALBERTO | E11: 34000 | F11: 34000 | G11: 0
A12: 11 | B12: 1252 | C12: 3492774 | D12: GARCIA CABELLO, ROQUE DOMINGO | E12: 34000 | F12: 34000 | G12: 0
A13: 12 | B13: 1261 | C13: 2056583 | D13: GONZALEZ PINO, JOEL JEREMIAS | E13: 1743932 | F13: 1743932 | G13: 0
... A972: 971 | B972: 13722 | C972: 5051335 | D972: HUERTA NOBLIA, DOMINGO JAVIER | E972: 263386 | F972: 263386 | G972: 0
A973: Total General | E973: =SUM(E2:E972) -> 660897511 | F973: =SUM(F2:F972) -> 425985496 | G973: =SUM(G2:G972) -> 234912015

Sheet Unidad 24
A1: N° | B1: N° Socio | C1: N° de CI | D1: Apellido y Nombre | E1: Total Descuentos | F1: Cobrado | G1: Rechazado
A2: 1 | B2: =IFERROR(INDEX(Hoja1!A:A,MATCH(C2,Hoja1!C:C,0)),"") -> 6846 | C2: 5165240 | D2: =IFERROR(INDEX(Hoja1!B:B,MATCH(C2,Hoja1!C:C,0)),"") -> ROA ACOSTA, GUSTAVO | E2: 34000 | F2: 34000 | G2: =E2-F2 -> 0
A3: 2 | B3: =IFERROR(INDEX(Hoja1!A:A,MATCH(C3,Hoja1!C:C,0)),"") -> 8389 | C3: 5792167 | D3: =IFERROR(INDEX(Hoja1!B:B,MATCH(C3,Hoja1!C:C,0)),"") -> CHAMORRO ARCE, BERNARDO | E3: 293608 | F3: 293608 | G3: =E3-F3 -> 0
A4: 3 | B4: =IFERROR(INDEX(Hoja1!A:A,MATCH(C4,Hoja1!C:C,0)),"") -> 12400 | C4: 5689460 | D4: =IFERROR(INDEX(Hoja1!B:B,MATCH(C4,Hoja1!C:C,0)),"") -> CONTESSI FILIPPINI, ENZO MIGUEL ANGEL | E4: 34000 | F4: 34000 | G4: =E4-F4 -> 0
A5: Total General | E5: =SUM(E2:E4) -> 361608 | F5: =SUM(F2:F4) -> 361608 | G5: =SUM(G2:G4) -> 0

Sheet Unidad 25
A1: N° | B1: N° Socio | C1: N° de CI | D1: Apellido y Nombre | E1: Total Descuentos | F1: Cobrado | G1: Rechazado
A2: 1 | B2: =IFERROR(INDEX(Hoja1!A:A,MATCH(C2,Hoja1!C:C,0)),"") -> 5328 | C2: 5246005 | D2: =IFERROR(INDEX(Hoja1!B:B,MATCH(C2,Hoja1!C:C,0)),"") -> SOSA BERNAL, MIGDONIO SAUL | E2: 1102900 | F2: 0 | G2: =E2-F2 -> 1102900
A3: =A2+1 -> 2 | B3: =IFERROR(INDEX(Hoja1!A:A,MATCH(C3,Hoja1!C:C,0)),"") -> 6456 | C3: 5521588 | D3: =IFERROR(INDEX(Hoja1!B:B,MATCH(C3,Hoja1!C:C,0)),"") -> OTAZU SANCHEZ, JUAN ANGEL RAFAEL | E3: 34000 | F3: 0 | G3: =E3-F3 -> 34000
A4: =A3+1 -> 3 | B4: =IFERROR(INDEX(Hoja1!A:A,MATCH(C4,Hoja1!C:C,0)),"") -> 8860 | C4: 7386617 | D4: =IFERROR(INDEX(Hoja1!B:B,MATCH(C4,Hoja1!C:C,0)),"") -> GARCIA LOPEZ, JULIO CESAR | E4: 1019578 | F4: 1019578 | G4: =E4-F4 -> 0
A5: =A4+1 -> 4 | B5: =IFERROR(INDEX(Hoja1!A:A,MATCH(C5,Hoja1!C:C,0)),"") -> 11355 | C5: 2580341 | D5: =IFERROR(INDEX(Hoja1!B:B,MATCH(C5,Hoja1!C:C,0)),"") -> ARIAS DE VARGAS, ADELIANA BEATRIZ | E5: 690659 | F5: 690659 | G5: =E5-F5 -> 0
A6: =A5+1 -> 5 | B6: =IFERROR(INDEX(Hoja1!A:A,MATCH(C6,Hoja1!C:C,0)),"") -> 11980 | C6: 3629090 | D6: =IFERROR(INDEX(Hoja1!B:B,MATCH(C6,Hoja1!C:C,0)),"") -> MATORO CHILENO, ALBERTO | E6: 690659 | F6: 690659 | G6: =E6-F6 -> 0
A7: =A6+1 -> 6 | B7: =IFERROR(INDEX(Hoja1!A:A,MATCH(C7,Hoja1!C:C,0)),"") -> 12185 | C7: 4228599 | D7: =IFERROR(INDEX(Hoja1!B:B,MATCH(C7,Hoja1!C:C,0)),"") -> DIAZ ESCOBAR, WILFRIDO | E7: 375690 | F7: 375690 | G7: =E7-F7 -> 0
A8: Total General | E8: =SUM(E2:E7) -> 3913486 | F8: =SUM(F2:F7) -> 2776586 | G8: =SUM(G2:G7) -> 1136900

Sheet Unidad 26
A1: N° | B1: N° Socio | C1: N° de CI | D1: Apellido y Nombre | E1: Total Descuentos | F1: Cobrado | G1: Rechazado
A2: 1 | B2: =IFERROR(INDEX(Hoja1!A:A,MATCH(C2,Hoja1!C:C,0)),"") -> 801 | C2: 625866 | D2: =IFERROR(INDEX(Hoja1!B:B,MATCH(C2,Hoja1!C:C,0)),"") -> SANCHEZ ABAD, MARIA ANGELA | E2: 647151 | F2: 0 | G2: =E2-F2 -> 647151
A3: =A2+1 -> 2 | B3: =IFERROR(INDEX(Hoja1!A:A,MATCH(C3,Hoja1!C:C,0)),"") -> 1459 | C3: 1056003 | D3: =IFERROR(INDEX(Hoja1!B:B,MATCH(C3,Hoja1!C:C,0)),"") -> LOPEZ LUGO, NELSON DARIO | E3: 34000 | F3: 34000 | G3: =E3-F3 -> 0
A4: =A3+1 -> 3 | B4: =IFERROR(INDEX(Hoja1!A:A,MATCH(C4,Hoja1!C:C,0)),"") -> 2153 | C4: 2361619 | D4: =IFERROR(INDEX(Hoja1!B:B,MATCH(C4,Hoja1!C:C,0)),"") -> DOMINGUEZ ARECO, FREDY YSMAEL | E4: 690659 | F4: 0 | G4: =E4-F4 -> 690659
A5: =A4+1 -> 4 | B5: =IFERROR(INDEX(Hoja1!A:A,MATCH(C5,Hoja1!C:C,0)),"") -> 6096 | C5: 4042333 | D5: =IFERROR(INDEX(Hoja1!B:B,MATCH(C5,Hoja1!C:C,0)),"") -> PAGLIARO RUIZ, JORGE CAMILO | E5: 364520 | F5: 0 | G5: =E5-F5 -> 364520
A6: =A5+1 -> 5 | B6: =IFERROR(INDEX(Hoja1!A:A,MATCH(C6,Hoja1!C:C,0)),"") -> 7896 | C6: 5737572 | D6: =IFERROR(INDEX(Hoja1!B:B,MATCH(C6,Hoja1!C:C,0)),"") -> SAMUDIO SAMANIEGO, ALEX JAVIER | E6: 34000 | F6: 34000 | G6: =E6-F6 -> 0
A7: =A6+1 -> 6 | B7: =IFERROR(INDEX(Hoja1!A:A,MATCH(C7,Hoja1!C:C,0)),"") -> 7965 | C7: 6741267 | D7: =IFERROR(INDEX(Hoja1!B:B,MATCH(C7,Hoja1!C:C,0)),"") -> GONZALEZ LOPEZ, HERIBERTO FROILAN | E7: 1157388 | F7: 1157388 | G7: =E7-F7 -> 0
A8: =A7+1 -> 7 | B8: =IFERROR(INDEX(Hoja1!A:A,MATCH(C8,Hoja1!C:C,0)),"") -> 8128 | C8: 6822090 | D8: =IFERROR(INDEX(Hoja1!B:B,MATCH(C8,Hoja1!C:C,0)),"") -> GARAY ESCOBAR, JUAN MANUEL | E8: 868016 | F8: 868016 | G8: =E8-F8 -> 0
A9: =A8+1 -> 8 | B9: =IFERROR(INDEX(Hoja1!A:A,MATCH(C9,Hoja1!C:C,0)),"") -> 8660 | C9: 6286532 | D9: =IFERROR(INDEX(Hoja1!B:B,MATCH(C9,Hoja1!C:C,0)),"") -> ACOSTA ESQUIVEL, JUAN ANGEL | E9: 1607208 | F9: 0 | G9: =E9-F9 -> 1607208
A10: =A9+1 -> 9 | B10: =IFERROR(INDEX(Hoja1!A:A,MATCH(C10,Hoja1!C:C,0)),"") -> 8661 | C10: 6133948 | D10: =IFERROR(INDEX(Hoja1!B:B,MATCH(C10,Hoja1!C:C,0)),"") -> SANCHEZ, FAUTINO | E10: 156452 | F10: 156452 | G10: =E10-F10 -> 0
A11: =A10+1 -> 10 | B11: =IFERROR(INDEX(Hoja1!A:A,MATCH(C11,Hoja1!C:C,0)),"") -> 9533 | C11: 5945199 | D11: =IFERROR(INDEX(Hoja1!B:B,MATCH(C11,Hoja1!C:C,0)),"") -> VILLAR RICARDI, ANIBAL | E11: 1039211 | F11: 1039211 | G11: =E11-F11 -> 0
A12: =A11+1 -> 11 | B12: =IFERROR(INDEX(Hoja1!A:A,MATCH(C12,Hoja1!C:C,0)),"") -> 10467 | C12: 5691561 | D12: =IFERROR(INDEX(Hoja1!B:B,MATCH(C12,Hoja1!C:C,0)),"") -> ORTIZ DIAZ, VICTOR DANIEL | E12: 307608 | F12: 34000 | G12: =E12-F12 -> 273608
A13: =A12+1 -> 12 | B13: =IFERROR(INDEX(Hoja1!A:A,MATCH(C13,Hoja1!C:C,0)),"") -> 10998 | C13: 5083792 | D13: =IFERROR(INDEX(Hoja1!B:B,MATCH(C13,Hoja1!C:C,0)),"") -> GOMEZ GONZALEZ, FABIO | E13: 34000 | F13: 34000 | G13: =E13-F13 -> 0
A14: =A13+1 -> 13 | B14: =IFERROR(INDEX(Hoja1!A:A,MATCH(C14,Hoja1!C:C,0)),"") -> 12425 | C14: 5939035 | D14: =IFERROR(INDEX(Hoja1!B:B,MATCH(C14,Hoja1!C:C,0)),"") -> ESPINOLA LOPEZ, GABRIEL | E14: 993118 | F14: 993118 | G14: =E14-F14 -> 0
A15: Total General | E15: =SUM(E2:E14) -> 7933331 | F15: =SUM(F2:F14) -> 4350185 | G15: =SUM(G2:G14) -> 3583146

Sheet Unidad 27
A1: N° | B1: N° Socio | C1: N° de CI | D1: Apellido y Nombre | E1: Total Descuentos | F1: Cobrado | G1: Rechazado
A2: 1 | B2: =IFERROR(INDEX(Hoja1!A:A,MATCH(C2,Hoja1!C:C,0)),"") -> 8059 | C2: 6214750 | D2: =IFERROR(INDEX(Hoja1!B:B,MATCH(C2,Hoja1!C:C,0)),"") -> RIVEROS BOGADO, GERMAN | E2: 1760178 | F2: 1760178 | G2: =E2-F2 -> 0

Sheet Unidad 28
A1: N° | B1: N° Socio | C1: N° de CI | D1: Apellido y Nombre | E1: Total Descuentos | F1: Cobrado | G1: Rechazado
A2: 1 | B2: =IFERROR(INDEX(Hoja1!A:A,MATCH(C2,Hoja1!C:C,0)),"") -> 5025 | C2: 5010155 | D2: =IFERROR(INDEX(Hoja1!B:B,MATCH(C2,Hoja1!C:C,0)),"") -> TOLEDO ORTIZ, PEDRO MILCIADES | E2: 634410 | F2: 634410 | G2: =E2-F2 -> 0
A3: 2 | B3: =IFERROR(INDEX(Hoja1!A:A,MATCH(C3,Hoja1!C:C,0)),"") -> 8279 | C3: 5130263 | D3: =IFERROR(INDEX(Hoja1!B:B,MATCH(C3,Hoja1!C:C,0)),"") -> PEREIRA, DIEGO RODRIGO | E3: 725775 | F3: 725775 | G3: =E3-F3 -> 0
A4: 3 | B4: =IFERROR(INDEX(Hoja1!A:A,MATCH(C4,Hoja1!C:C,0)),"") -> 11013 | C4: 7600132 | D4: =IFERROR(INDEX(Hoja1!B:B,MATCH(C4,Hoja1!C:C,0)),"") -> ACOSTA ESQUIVEL, GERARDO | E4: 382573 | F4: 0 | G4: =E4-F4 -> 382573
A5: Total General | E5: =SUM(E2:E4) -> 1742758 | F5: =SUM(F2:F4) -> 1360185 | G5: =SUM(G2:G4) -> 382573

Sheet Unidad 29
A1: N° | B1: N° Socio | C1: N° de CI | D1: Apellido y Nombre | E1: Total Descuentos | F1: Cobrado | G1: Rechazado
A2: 1 | B2: =IFERROR(INDEX(Hoja1!A:A,MATCH(C2,Hoja1!C:C,0)),"") -> 5096 | C2: 5427404 | D2: =IFERROR(INDEX(Hoja1!B:B,MATCH(C2,Hoja1!C:C,0)),"") -> LOPEZ PEREIRA, JUAN CARLOS | E2: 690659 | F2: 690659 | G2: =E2-F2 -> 0
A3: =A2+1 -> 2 | B3: =IFERROR(INDEX(Hoja1!A:A,MATCH(C3,Hoja1!C:C,0)),"") -> 5959 | C3: 4352823 | D3: =IFERROR(INDEX(Hoja1!B:B,MATCH(C3,Hoja1!C:C,0)),"") -> FLORES RIOS, ANGEL GREGORIO | E3: 534410 | F3: 534410 | G3: =E3-F3 -> 0
A4: =A3+1 -> 3 | B4: =IFERROR(INDEX(Hoja1!A:A,MATCH(C4,Hoja1!C:C,0)),"") -> 7403 | C4: 4430234 | D4: =IFERROR(INDEX(Hoja1!B:B,MATCH(C4,Hoja1!C:C,0)),"") -> ROMERO CACERES, CARLOS MOISES | E4: 54000 | F4: 54000 | G4: =E4-F4 -> 0
A5: =A4+1 -> 4 | B5: =IFERROR(INDEX(Hoja1!A:A,MATCH(C5,Hoja1!C:C,0)),"") -> 7517 | C5: 5658367 | D5: =IFERROR(INDEX(Hoja1!B:B,MATCH(C5,Hoja1!C:C,0)),"") -> BENITEZ GALEANO, CELSO | E5: 817635 | F5: 817635 | G5: =E5-F5 -> 0
A6: =A5+1 -> 5 | B6: =IFERROR(INDEX(Hoja1!A:A,MATCH(C6,Hoja1!C:C,0)),"") -> 7520 | C6: 4806134 | D6: =IFERROR(INDEX(Hoja1!B:B,MATCH(C6,Hoja1!C:C,0)),"") -> MARIN ORTIZ, DAVID ENMANUEL | E6: 54000 | F6: 54000 | G6: =E6-F6 -> 0
A7: =A6+1 -> 6 | B7: =IFERROR(INDEX(Hoja1!A:A,MATCH(C7,Hoja1!C:C,0)),"") -> 7521 | C7: 3225949 | D7: =IFERROR(INDEX(Hoja1!B:B,MATCH(C7,Hoja1!C:C,0)),"") -> OVIEDO DELGADO, HUMBERTO | E7: 154000 | F7: 154000 | G7: =E7-F7 -> 0
A8: =A7+1 -> 7 | B8: =IFERROR(INDEX(Hoja1!A:A,MATCH(C8,Hoja1!C:C,0)),"") -> 9740 | C8: 3648169 | D8: =IFERROR(INDEX(Hoja1!B:B,MATCH(C8,Hoja1!C:C,0)),"") -> PRATTES CORVALAN, HUGO GREGORIO | E8: 990197 | F8: 0 | G8: =E8-F8 -> 990197
A9: Total General | E9: =SUM(E2:E8) -> 3294901 | F9: =SUM(F2:F8) -> 2304704 | G9: =SUM(G2:G8) -> 990197

Sheet Unidad 30
A1: N° | B1: N° Socio | C1: N° de CI | D1: Apellido y Nombre | E1: Total Descuentos | F1: Cobrado | G1: Rechazado
A2: 1 | B2: =IFERROR(INDEX(Hoja1!A:A,MATCH(C2,Hoja1!C:C,0)),"") -> 4977 | C2: 5356436 | D2: =IFERROR(INDEX(Hoja1!B:B,MATCH(C2,Hoja1!C:C,0)),"") -> ALVAREZ GALLO, JOSE EDUARDO | E2: 1074360 | F2: 0 | G2: =E2-F2 -> 1074360
A3: =A2+1 -> 2 | B3: =IFERROR(INDEX(Hoja1!A:A,MATCH(C3,Hoja1!C:C,0)),"") -> 7507 | C3: 5419557 | D3: =IFERROR(INDEX(Hoja1!B:B,MATCH(C3,Hoja1!C:C,0)),"") -> ROTELA, CARLOS JAVIER | E3: 30000 | F3: 30000 | G3: =E3-F3 -> 0
A4: =A3+1 -> 3 | B4: =IFERROR(INDEX(Hoja1!A:A,MATCH(C4,Hoja1!C:C,0)),"") -> 7510 | C4: 5122339 | D4: =IFERROR(INDEX(Hoja1!B:B,MATCH(C4,Hoja1!C:C,0)),"") -> GOMEZ BAREIRO, PASCUAL | E4: 34000 | F4: 34000 | G4: =E4-F4 -> 0
A5: =A4+1 -> 4 | B5: =IFERROR(INDEX(Hoja1!A:A,MATCH(C5,Hoja1!C:C,0)),"") -> 7546 | C5: 4165039 | D5: =IFERROR(INDEX(Hoja1!B:B,MATCH(C5,Hoja1!C:C,0)),"") -> GONZALEZ DUARTE, GABINO RAFAEL | E5: 1312922 | F5: 1312922 | G5: =E5-F5 -> 0
A6: =A5+1 -> 5 | B6: =IFERROR(INDEX(Hoja1!A:A,MATCH(C6,Hoja1!C:C,0)),"") -> 7615 | C6: 4245135 | D6: =IFERROR(INDEX(Hoja1!B:B,MATCH(C6,Hoja1!C:C,0)),"") -> BOGARIN MERELES, WALDEMAR | E6: 539692 | F6: 0 | G6: =E6-F6 -> 539692
A7: =A6+1 -> 6 | B7: =IFERROR(INDEX(Hoja1!A:A,MATCH(C7,Hoja1!C:C,0)),"") -> 8148 | C7: 6714180 | D7: =IFERROR(INDEX(Hoja1!B:B,MATCH(C7,Hoja1!C:C,0)),"") -> ORTIZ CARDOZO, AMELIO LEONOR | E7: 34000 | F7: 34000 | G7: =E7-F7 -> 0
A8: =A7+1 -> 7 | B8: =IFERROR(INDEX(Hoja1!A:A,MATCH(C8,Hoja1!C:C,0)),"") -> 9365 | C8: 5854844 | D8: =IFERROR(INDEX(Hoja1!B:B,MATCH(C8,Hoja1!C:C,0)),"") -> FLOR SOSA, ALDO JAVIER | E8: 1032181 | F8: 1032181 | G8: =E8-F8 -> 0
A9: =A8+1 -> 8 | B9: =IFERROR(INDEX(Hoja1!A:A,MATCH(C9,Hoja1!C:C,0)),"") -> 9388 | C9: 2097725 | D9: =IFERROR(INDEX(Hoja1!B:B,MATCH(C9,Hoja1!C:C,0)),"") -> BAREIRO FERNANDEZ, JOSE LEON | E9: 2733341 | F9: 0 | G9: =E9-F9 -> 2733341
A10: =A9+1 -> 9 | B10: =IFERROR(INDEX(Hoja1!A:A,MATCH(C10,Hoja1!C:C,0)),"") -> 9440 | C10: 2991104 | D10: =IFERROR(INDEX(Hoja1!B:B,MATCH(C10,Hoja1!C:C,0)),"") -> ZARATE BENITEZ, JUAN ANGEL | E10: 928970 | F10: 400000 | G10: =E10-F10 -> 528970
A11: =A10+1 -> 10 | B11: =IFERROR(INDEX(Hoja1!A:A,MATCH(C11,Hoja1!C:C,0)),"") -> 9834 | C11: 5836704 | D11: =IFERROR(INDEX(Hoja1!B:B,MATCH(C11,Hoja1!C:C,0)),"") -> AQUINO, JULIO CESAR | E11: 34000 | F11: 34000 | G11: =E11-F11 -> 0
A12: =A11+1 -> 11 | B12: =IFERROR(INDEX(Hoja1!A:A,MATCH(C12,Hoja1!C:C,0)),"") -> 9840 | C12: 5262037 | D12: =IFERROR(INDEX(Hoja1!B:B,MATCH(C12,Hoja1!C:C,0)),"") -> GONZALEZ ESPINOLA, LUIS SALVADOR | E12: 854824 | F12: 854824 | G12: =E12-F12 -> 0
A13: =A12+1 -> 12 | B13: =IFERROR(INDEX(Hoja1!A:A,MATCH(C13,Hoja1!C:C,0)),"") -> 10189 | C13: 6279059 | D13: =IFERROR(INDEX(Hoja1!B:B,MATCH(C13,Hoja1!C:C,0)),"") -> ALVARENGA, EMANUEL DEJESUS | E13: 1011128 | F13: 1011128 | G13: =E13-F13 -> 0
A14: =A13+1 -> 13 | B14: =IFERROR(INDEX(Hoja1!A:A,MATCH(C14,Hoja1!C:C,0)),"") -> 11084 | C14: 4854175 | D14: =IFERROR(INDEX(Hoja1!B:B,MATCH(C14,Hoja1!C:C,0)),"") -> RAMIREZ BENITEZ, LUIS ALBERTO | E14: 34000 | F14: 34000 | G14: =E14-F14 -> 0
... A19: =A18+1 -> 18 | B19: =IFERROR(INDEX(Hoja1!A:A,MATCH(C19,Hoja1!C:C,0)),"") -> 12529 | C19: 5751624 | D19: =IFERROR(INDEX(Hoja1!B:B,MATCH(C19,Hoja1!C:C,0)),"") -> GONZALEZ VERA, FABIO LUIS | E19: 365194 | F19: 365194 | G19: =E19-F19 -> 0
A20: Total General | E20: =SUM(E2:E19) -> 12609895 | F20: =SUM(F2:F19) -> 7480164 | G20: =SUM(G2:G19) -> 5129731

Sheet Unidad 31
A1: N° | B1: N° Socio | C1: N° de CI | D1: Apellido y Nombre | E1: Total Descuentos | F1: Cobrado | G1: Rechazado
A2: 1 | B2: =IFERROR(INDEX(Hoja1!A:A,MATCH(C2,Hoja1!C:C,0)),"") -> 1113 | C2: 2082271 | D2: =IFERROR(INDEX(Hoja1!B:B,MATCH(C2,Hoja1!C:C,0)),"") -> ROLON, CYNTHIA ESMILCE | E2: 618726 | F2: 0 | G2: =E2-F2 -> 618726
A3: =A2+1 -> 2 | B3: =IFERROR(INDEX(Hoja1!A:A,MATCH(C3,Hoja1!C:C,0)),"") -> 1230 | C3: 561170 | D3: =IFERROR(INDEX(Hoja1!B:B,MATCH(C3,Hoja1!C:C,0)),"") -> SERVIN, LADISLAO | E3: 34000 | F3: 34000 | G3: =E3-F3 -> 0
A4: =A3+1 -> 3 | B4: =IFERROR(INDEX(Hoja1!A:A,MATCH(C4,Hoja1!C:C,0)),"") -> 2998 | C4: 3515731 | D4: =IFERROR(INDEX(Hoja1!B:B,MATCH(C4,Hoja1!C:C,0)),"") -> CORONEL CESPEDES, ALBERTO RODOLFO | E4: 1162728 | F4: 0 | G4: =E4-F4 -> 1162728
A5: =A4+1 -> 4 | B5: =IFERROR(INDEX(Hoja1!A:A,MATCH(C5,Hoja1!C:C,0)),"") -> 3071 | C5: 1680934 | D5: =IFERROR(INDEX(Hoja1!B:B,MATCH(C5,Hoja1!C:C,0)),"") -> RUIZ DIAZ PRIETO, JULIO DANIEL | E5: 312283 | F5: 302760 | G5: =E5-F5 -> 9523
A6: =A5+1 -> 5 | B6: =IFERROR(INDEX(Hoja1!A:A,MATCH(C6,Hoja1!C:C,0)),"") -> 3109 | C6: 3878458 | D6: =IFERROR(INDEX(Hoja1!B:B,MATCH(C6,Hoja1!C:C,0)),"") -> LEDEZMA CAZAL, ANIBAL | E6: 507272 | F6: 507272 | G6: =E6-F6 -> 0
A7: =A6+1 -> 6 | B7: =IFERROR(INDEX(Hoja1!A:A,MATCH(C7,Hoja1!C:C,0)),"") -> 3285 | C7: 3009699 | D7: =IFERROR(INDEX(Hoja1!B:B,MATCH(C7,Hoja1!C:C,0)),"") -> CANDIA FLORENTIN, NARCISO | E7: 54000 | F7: 54000 | G7: =E7-F7 -> 0
A8: =A7+1 -> 7 | B8: =IFERROR(INDEX(Hoja1!A:A,MATCH(C8,Hoja1!C:C,0)),"") -> 3387 | C8: 2934366 | D8: =IFERROR(INDEX(Hoja1!B:B,MATCH(C8,Hoja1!C:C,0)),"") -> NOGUERA SANABRIA, ANTONIO RAMON | E8: 800199 | F8: 0 | G8: =E8-F8 -> 800199
A9: =A8+1 -> 8 | B9: =IFERROR(INDEX(Hoja1!A:A,MATCH(C9,Hoja1!C:C,0)),"") -> 3478 | C9: 1335269 | D9: =IFERROR(INDEX(Hoja1!B:B,MATCH(C9,Hoja1!C:C,0)),"") -> AZARI, MARCIAL | E9: 460459 | F9: 460459 | G9: =E9-F9 -> 0
A10: =A9+1 -> 9 | B10: =IFERROR(INDEX(Hoja1!A:A,MATCH(C10,Hoja1!C:C,0)),"") -> 3546 | C10: 734898 | D10: =IFERROR(INDEX(Hoja1!B:B,MATCH(C10,Hoja1!C:C,0)),"") -> SILVA, ARMINDA | E10: 1097079 | F10: 791600 | G10: =E10-F10 -> 305479
A11: =A10+1 -> 10 | B11: =IFERROR(INDEX(Hoja1!A:A,MATCH(C11,Hoja1!C:C,0)),"") -> 3640 | C11: 815837 | D11: =IFERROR(INDEX(Hoja1!B:B,MATCH(C11,Hoja1!C:C,0)),"") -> PORTILLO MONGES, GABRIEL | E11: 802957 | F11: 234000 | G11: =E11-F11 -> 568957
A12: =A11+1 -> 11 | B12: =IFERROR(INDEX(Hoja1!A:A,MATCH(C12,Hoja1!C:C,0)),"") -> 3699 | C12: 4577428 | D12: =IFERROR(INDEX(Hoja1!B:B,MATCH(C12,Hoja1!C:C,0)),"") -> VARGAS CAÑIZA, EDGAR | E12: 967923 | F12: 967923 | G12: =E12-F12 -> 0
A13: =A12+1 -> 12 | B13: =IFERROR(INDEX(Hoja1!A:A,MATCH(C13,Hoja1!C:C,0)),"") -> 3917 | C13: 694132 | D13: =IFERROR(INDEX(Hoja1!B:B,MATCH(C13,Hoja1!C:C,0)),"") -> GUTIERREZ DE LOS SANTOS, CARLOS | E13: 34000 | F13: 34000 | G13: =E13-F13 -> 0
A14: =A13+1 -> 13 | B14: =IFERROR(INDEX(Hoja1!A:A,MATCH(C14,Hoja1!C:C,0)),"") -> 3931 | C14: 1067173 | D14: =IFERROR(INDEX(Hoja1!B:B,MATCH(C14,Hoja1!C:C,0)),"") -> BARBOZA DE GUTIERREZ, MYRIAN CATALINA | E14: 963893 | F14: 963893 | G14: =E14-F14 -> 0
... A75: =A74+1 -> 74 | B75: =IFERROR(INDEX(Hoja1!A:A,MATCH(C75,Hoja1!C:C,0)),"") -> 13474 | C75: 6826760 | D75: =IFERROR(INDEX(Hoja1!B:B,MATCH(C75,Hoja1!C:C,0)),"") -> GUAYAN ARAUJO, REINALDO RAMON | E75: 54000 | F75: 54000 | G75: =E75-F75 -> 0
A76: Total General | E76: =SUM(E2:E75) -> 52097231 | F76: =SUM(F2:F75) -> 41580497 | G76: =SUM(G2:G75) -> 10516734

Sheet Unidad 32
A1: N° | B1: N° Socio | C1: N° de CI | D1: Apellido y Nombre | E1: Total Descuentos | F1: Cobrado | G1: Rechazado
A2: 1 | B2: =IFERROR(INDEX(Hoja1!A:A,MATCH(C2,Hoja1!C:C,0)),"") -> 5163 | C2: 4600852 | D2: =IFERROR(INDEX(Hoja1!B:B,MATCH(C2,Hoja1!C:C,0)),"") -> CABALLERO BENITEZ, JUSTINO | E2: 1322473 | F2: 1322473 | G2: =E2-F2 -> 0
A3: =A2+1 -> 2 | B3: =IFERROR(INDEX(Hoja1!A:A,MATCH(C3,Hoja1!C:C,0)),"") -> 5884 | C3: 5046137 | D3: =IFERROR(INDEX(Hoja1!B:B,MATCH(C3,Hoja1!C:C,0)),"") -> ROA SANGUINA, DIEGO MANUEL | E3: 1421546 | F3: 1421546 | G3: =E3-F3 -> 0
A4: =A3+1 -> 3 | B4: =IFERROR(INDEX(Hoja1!A:A,MATCH(C4,Hoja1!C:C,0)),"") -> 7738 | C4: 3611915 | D4: =IFERROR(INDEX(Hoja1!B:B,MATCH(C4,Hoja1!C:C,0)),"") -> ESCOBAR CORONEL, ARNALDO GABRIEL | E4: 591827 | F4: 0 | G4: =E4-F4 -> 591827
A5: =A4+1 -> 4 | B5: =IFERROR(INDEX(Hoja1!A:A,MATCH(C5,Hoja1!C:C,0)),"") -> 8032 | C5: 6526015 | D5: =IFERROR(INDEX(Hoja1!B:B,MATCH(C5,Hoja1!C:C,0)),"") -> RODRIGUEZ CALDERON, PACIANO ADRIAN | E5: 878682 | F5: 148682 | G5: =E5-F5 -> 730000
A6: =A5+1 -> 5 | B6: =IFERROR(INDEX(Hoja1!A:A,MATCH(C6,Hoja1!C:C,0)),"") -> 8410 | C6: 4020902 | D6: =IFERROR(INDEX(Hoja1!B:B,MATCH(C6,Hoja1!C:C,0)),"") -> CABAÑA GONZALEZ, JULIO CESAR | E6: 586776 | F6: 586776 | G6: =E6-F6 -> 0
A7: =A6+1 -> 6 | B7: =IFERROR(INDEX(Hoja1!A:A,MATCH(C7,Hoja1!C:C,0)),"") -> 8562 | C7: 5531680 | D7: =IFERROR(INDEX(Hoja1!B:B,MATCH(C7,Hoja1!C:C,0)),"") -> MEDINA CANO, SANTIAGO | E7: 520410 | F7: 520410 | G7: =E7-F7 -> 0
A8: =A7+1 -> 7 | B8: =IFERROR(INDEX(Hoja1!A:A,MATCH(C8,Hoja1!C:C,0)),"") -> 8927 | C8: 5067679 | D8: =IFERROR(INDEX(Hoja1!B:B,MATCH(C8,Hoja1!C:C,0)),"") -> RODRIGUEZ FRANCO, DANILO CAYETANO | E8: 1163918 | F8: 633918 | G8: =E8-F8 -> 530000
A9: =A8+1 -> 8 | B9: =IFERROR(INDEX(Hoja1!A:A,MATCH(C9,Hoja1!C:C,0)),"") -> 8992 | C9: 6333082 | D9: =IFERROR(INDEX(Hoja1!B:B,MATCH(C9,Hoja1!C:C,0)),"") -> ORTEGA GONZALEZ, DERLIS | E9: 34000 | F9: 34000 | G9: =E9-F9 -> 0
A10: =A9+1 -> 9 | B10: =IFERROR(INDEX(Hoja1!A:A,MATCH(C10,Hoja1!C:C,0)),"") -> 9216 | C10: 1773481 | D10: =IFERROR(INDEX(Hoja1!B:B,MATCH(C10,Hoja1!C:C,0)),"") -> FRUTOS VARGAS, TOMAS ALAN | E10: 34000 | F10: 34000 | G10: =E10-F10 -> 0
A11: =A10+1 -> 10 | B11: =IFERROR(INDEX(Hoja1!A:A,MATCH(C11,Hoja1!C:C,0)),"") -> 9688 | C11: 5193789 | D11: =IFERROR(INDEX(Hoja1!B:B,MATCH(C11,Hoja1!C:C,0)),"") -> CABRERA NUÑEZ, YHONY DANIEL | E11: 971232 | F11: 971232 | G11: =E11-F11 -> 0
A12: =A11+1 -> 11 | B12: =IFERROR(INDEX(Hoja1!A:A,MATCH(C12,Hoja1!C:C,0)),"") -> 10016 | C12: 6704709 | D12: =IFERROR(INDEX(Hoja1!B:B,MATCH(C12,Hoja1!C:C,0)),"") -> FRUTOS MEDINA, FERMIN | E12: 134000 | F12: 134000 | G12: =E12-F12 -> 0
A13: =A12+1 -> 12 | B13: =IFERROR(INDEX(Hoja1!A:A,MATCH(C13,Hoja1!C:C,0)),"") -> 10265 | C13: 6166566 | D13: =IFERROR(INDEX(Hoja1!B:B,MATCH(C13,Hoja1!C:C,0)),"") -> GONZALEZ, YUNIOR DAVID | E13: 534410 | F13: 534410 | G13: =E13-F13 -> 0
A14: =A13+1 -> 13 | B14: =IFERROR(INDEX(Hoja1!A:A,MATCH(C14,Hoja1!C:C,0)),"") -> 10487 | C14: 6521748 | D14: =IFERROR(INDEX(Hoja1!B:B,MATCH(C14,Hoja1!C:C,0)),"") -> BENITEZ DELVALLE, NELSON RAMON | E14: 994913 | F14: 994913 | G14: =E14-F14 -> 0
... A30: =A29+1 -> 29 | B30: =IFERROR(INDEX(Hoja1!A:A,MATCH(C30,Hoja1!C:C,0)),"") -> 13189 | C30: 5067701 | D30: =IFERROR(INDEX(Hoja1!B:B,MATCH(C30,Hoja1!C:C,0)),"") -> SOSA OCAMPO, NERY LUIS | E30: 607003 | F30: 607003 | G30: =E30-F30 -> 0
A31: Total General | E31: =SUM(E2:E30) -> 20102602 | F31: =SUM(F2:F30) -> 16568849 | G31: =SUM(G2:G30) -> 3533753

Sheet Unidad 35
A1: N° | B1: N° Socio | C1: N° de CI | D1: Apellido y Nombre | E1: Total Descuentos | F1: Cobrado | G1: Rechazado
A2: 1 | B2: =IFERROR(INDEX(Hoja1!A:A,MATCH(C2,Hoja1!C:C,0)),"") -> 1501 | C2: 1888195 | D2: =IFERROR(INDEX(Hoja1!B:B,MATCH(C2,Hoja1!C:C,0)),"") -> GALVAN GARCIA, BENICIO RAUL | E2: 34000 | F2: 34000 | G2: =E2-F2 -> 0
A3: 2 | B3: =IFERROR(INDEX(Hoja1!A:A,MATCH(C3,Hoja1!C:C,0)),"") -> 2893 | C3: 4043909 | D3: =IFERROR(INDEX(Hoja1!B:B,MATCH(C3,Hoja1!C:C,0)),"") -> ROJAS TORRES, EMANUEL | E3: 1410321 | F3: 1410321 | G3: =E3-F3 -> 0
A4: 3 | B4: =IFERROR(INDEX(Hoja1!A:A,MATCH(C4,Hoja1!C:C,0)),"") -> 7779 | C4: 4043900 | D4: =IFERROR(INDEX(Hoja1!B:B,MATCH(C4,Hoja1!C:C,0)),"") -> ROJAS TORRES, EDEN | E4: 34000 | F4: 34000 | G4: =E4-F4 -> 0
A5: Total General | E5: =SUM(E2:E4) -> 1478321 | F5: =SUM(F2:F4) -> 1478321 | G5: =SUM(G2:G4) -> 0

Sheet Unidad 36
A1: N° | B1: N° Socio | C1: N° de CI | D1: Apellido y Nombre | E1: Total Descuentos | F1: Cobrado | G1: Rechazado
